Sep 22 15:33:25 minikube systemd[1]: Started kubelet: The Kubernetes Node Agent.
Sep 22 15:33:25 minikube kubelet[991]: Flag --cgroups-per-qos has been deprecated, This parameter should be set via the config file specified by the Kubelet's --config flag. See https://kubernetes.io/docs/tasks/administer-cluster/kubelet-config-file/ for more information.
Sep 22 15:33:25 minikube kubelet[991]: Flag --enforce-node-allocatable has been deprecated, This parameter should be set via the config file specified by the Kubelet's --config flag. See https://kubernetes.io/docs/tasks/administer-cluster/kubelet-config-file/ for more information.
Sep 22 15:33:25 minikube kubelet[991]: Flag --feature-gates has been deprecated, This parameter should be set via the config file specified by the Kubelet's --config flag. See https://kubernetes.io/docs/tasks/administer-cluster/kubelet-config-file/ for more information.
Sep 22 15:33:25 minikube kubelet[991]: E0922 15:33:25.539733     991 run.go:72] "command failed" err="failed to load kubelet config file, path: /var/lib/kubelet/config.yaml, error: failed to load Kubelet config file /var/lib/kubelet/config.yaml, error failed to read kubelet config file \"/var/lib/kubelet/config.yaml\", error: open /var/lib/kubelet/config.yaml: no such file or directory"
Sep 22 15:33:25 minikube systemd[1]: kubelet.service: Main process exited, code=exited, status=1/FAILURE
Sep 22 15:33:25 minikube systemd[1]: kubelet.service: Failed with result 'exit-code'.
Sep 22 15:33:26 minikube systemd[1]: kubelet.service: Scheduled restart job, restart counter is at 1.
Sep 22 15:33:26 minikube systemd[1]: Stopped kubelet: The Kubernetes Node Agent.
Sep 22 15:33:26 minikube systemd[1]: Started kubelet: The Kubernetes Node Agent.
Sep 22 15:33:26 minikube kubelet[1019]: Flag --cgroups-per-qos has been deprecated, This parameter should be set via the config file specified by the Kubelet's --config flag. See https://kubernetes.io/docs/tasks/administer-cluster/kubelet-config-file/ for more information.
Sep 22 15:33:26 minikube kubelet[1019]: Flag --enforce-node-allocatable has been deprecated, This parameter should be set via the config file specified by the Kubelet's --config flag. See https://kubernetes.io/docs/tasks/administer-cluster/kubelet-config-file/ for more information.
Sep 22 15:33:26 minikube kubelet[1019]: Flag --feature-gates has been deprecated, This parameter should be set via the config file specified by the Kubelet's --config flag. See https://kubernetes.io/docs/tasks/administer-cluster/kubelet-config-file/ for more information.
Sep 22 15:33:26 minikube kubelet[1019]: E0922 15:33:26.333964    1019 run.go:72] "command failed" err="failed to load kubelet config file, path: /var/lib/kubelet/config.yaml, error: failed to load Kubelet config file /var/lib/kubelet/config.yaml, error failed to read kubelet config file \"/var/lib/kubelet/config.yaml\", error: open /var/lib/kubelet/config.yaml: no such file or directory"
Sep 22 15:33:26 minikube systemd[1]: kubelet.service: Main process exited, code=exited, status=1/FAILURE
Sep 22 15:33:26 minikube systemd[1]: kubelet.service: Failed with result 'exit-code'.
Sep 22 15:33:26 minikube systemd[1]: kubelet.service: Scheduled restart job, restart counter is at 2.
Sep 22 15:33:26 minikube systemd[1]: Stopped kubelet: The Kubernetes Node Agent.
Sep 22 15:33:26 minikube systemd[1]: Started kubelet: The Kubernetes Node Agent.
Sep 22 15:33:27 minikube kubelet[1100]: Flag --cgroups-per-qos has been deprecated, This parameter should be set via the config file specified by the Kubelet's --config flag. See https://kubernetes.io/docs/tasks/administer-cluster/kubelet-config-file/ for more information.
Sep 22 15:33:27 minikube kubelet[1100]: Flag --enforce-node-allocatable has been deprecated, This parameter should be set via the config file specified by the Kubelet's --config flag. See https://kubernetes.io/docs/tasks/administer-cluster/kubelet-config-file/ for more information.
Sep 22 15:33:27 minikube kubelet[1100]: Flag --feature-gates has been deprecated, This parameter should be set via the config file specified by the Kubelet's --config flag. See https://kubernetes.io/docs/tasks/administer-cluster/kubelet-config-file/ for more information.
Sep 22 15:33:27 minikube kubelet[1100]: E0922 15:33:27.072810    1100 run.go:72] "command failed" err="failed to load kubelet config file, path: /var/lib/kubelet/config.yaml, error: failed to load Kubelet config file /var/lib/kubelet/config.yaml, error failed to read kubelet config file \"/var/lib/kubelet/config.yaml\", error: open /var/lib/kubelet/config.yaml: no such file or directory"
Sep 22 15:33:27 minikube systemd[1]: kubelet.service: Main process exited, code=exited, status=1/FAILURE
Sep 22 15:33:27 minikube systemd[1]: kubelet.service: Failed with result 'exit-code'.
Sep 22 15:33:27 minikube systemd[1]: kubelet.service: Scheduled restart job, restart counter is at 3.
Sep 22 15:33:27 minikube systemd[1]: Stopped kubelet: The Kubernetes Node Agent.
Sep 22 15:33:27 minikube systemd[1]: Started kubelet: The Kubernetes Node Agent.
Sep 22 15:33:27 minikube kubelet[1133]: Flag --cgroups-per-qos has been deprecated, This parameter should be set via the config file specified by the Kubelet's --config flag. See https://kubernetes.io/docs/tasks/administer-cluster/kubelet-config-file/ for more information.
Sep 22 15:33:27 minikube kubelet[1133]: Flag --enforce-node-allocatable has been deprecated, This parameter should be set via the config file specified by the Kubelet's --config flag. See https://kubernetes.io/docs/tasks/administer-cluster/kubelet-config-file/ for more information.
Sep 22 15:33:27 minikube kubelet[1133]: Flag --feature-gates has been deprecated, This parameter should be set via the config file specified by the Kubelet's --config flag. See https://kubernetes.io/docs/tasks/administer-cluster/kubelet-config-file/ for more information.
Sep 22 15:33:27 minikube kubelet[1133]: E0922 15:33:27.815325    1133 run.go:72] "command failed" err="failed to load kubelet config file, path: /var/lib/kubelet/config.yaml, error: failed to load Kubelet config file /var/lib/kubelet/config.yaml, error failed to read kubelet config file \"/var/lib/kubelet/config.yaml\", error: open /var/lib/kubelet/config.yaml: no such file or directory"
Sep 22 15:33:27 minikube systemd[1]: kubelet.service: Main process exited, code=exited, status=1/FAILURE
Sep 22 15:33:27 minikube systemd[1]: kubelet.service: Failed with result 'exit-code'.
Sep 22 15:33:28 minikube systemd[1]: kubelet.service: Scheduled restart job, restart counter is at 4.
Sep 22 15:33:28 minikube systemd[1]: Stopped kubelet: The Kubernetes Node Agent.
Sep 22 15:33:28 minikube systemd[1]: Started kubelet: The Kubernetes Node Agent.
Sep 22 15:33:28 minikube kubelet[1140]: Flag --cgroups-per-qos has been deprecated, This parameter should be set via the config file specified by the Kubelet's --config flag. See https://kubernetes.io/docs/tasks/administer-cluster/kubelet-config-file/ for more information.
Sep 22 15:33:28 minikube kubelet[1140]: Flag --enforce-node-allocatable has been deprecated, This parameter should be set via the config file specified by the Kubelet's --config flag. See https://kubernetes.io/docs/tasks/administer-cluster/kubelet-config-file/ for more information.
Sep 22 15:33:28 minikube kubelet[1140]: Flag --feature-gates has been deprecated, This parameter should be set via the config file specified by the Kubelet's --config flag. See https://kubernetes.io/docs/tasks/administer-cluster/kubelet-config-file/ for more information.
Sep 22 15:33:28 minikube kubelet[1140]: E0922 15:33:28.559579    1140 run.go:72] "command failed" err="failed to load kubelet config file, path: /var/lib/kubelet/config.yaml, error: failed to load Kubelet config file /var/lib/kubelet/config.yaml, error failed to read kubelet config file \"/var/lib/kubelet/config.yaml\", error: open /var/lib/kubelet/config.yaml: no such file or directory"
Sep 22 15:33:28 minikube systemd[1]: kubelet.service: Main process exited, code=exited, status=1/FAILURE
Sep 22 15:33:28 minikube systemd[1]: kubelet.service: Failed with result 'exit-code'.
Sep 22 15:33:29 minikube systemd[1]: kubelet.service: Scheduled restart job, restart counter is at 5.
Sep 22 15:33:29 minikube systemd[1]: Stopped kubelet: The Kubernetes Node Agent.
Sep 22 15:33:29 minikube systemd[1]: Started kubelet: The Kubernetes Node Agent.
Sep 22 15:33:29 minikube kubelet[1147]: Flag --cgroups-per-qos has been deprecated, This parameter should be set via the config file specified by the Kubelet's --config flag. See https://kubernetes.io/docs/tasks/administer-cluster/kubelet-config-file/ for more information.
Sep 22 15:33:29 minikube kubelet[1147]: Flag --enforce-node-allocatable has been deprecated, This parameter should be set via the config file specified by the Kubelet's --config flag. See https://kubernetes.io/docs/tasks/administer-cluster/kubelet-config-file/ for more information.
Sep 22 15:33:29 minikube kubelet[1147]: Flag --feature-gates has been deprecated, This parameter should be set via the config file specified by the Kubelet's --config flag. See https://kubernetes.io/docs/tasks/administer-cluster/kubelet-config-file/ for more information.
Sep 22 15:33:29 minikube kubelet[1147]: E0922 15:33:29.311171    1147 run.go:72] "command failed" err="failed to load kubelet config file, path: /var/lib/kubelet/config.yaml, error: failed to load Kubelet config file /var/lib/kubelet/config.yaml, error failed to read kubelet config file \"/var/lib/kubelet/config.yaml\", error: open /var/lib/kubelet/config.yaml: no such file or directory"
Sep 22 15:33:29 minikube systemd[1]: kubelet.service: Main process exited, code=exited, status=1/FAILURE
Sep 22 15:33:29 minikube systemd[1]: kubelet.service: Failed with result 'exit-code'.
Sep 22 15:33:29 minikube systemd[1]: kubelet.service: Scheduled restart job, restart counter is at 6.
Sep 22 15:33:29 minikube systemd[1]: Stopped kubelet: The Kubernetes Node Agent.
Sep 22 15:33:29 minikube systemd[1]: Started kubelet: The Kubernetes Node Agent.
Sep 22 15:33:30 minikube kubelet[1154]: Flag --cgroups-per-qos has been deprecated, This parameter should be set via the config file specified by the Kubelet's --config flag. See https://kubernetes.io/docs/tasks/administer-cluster/kubelet-config-file/ for more information.
Sep 22 15:33:30 minikube kubelet[1154]: Flag --enforce-node-allocatable has been deprecated, This parameter should be set via the config file specified by the Kubelet's --config flag. See https://kubernetes.io/docs/tasks/administer-cluster/kubelet-config-file/ for more information.
Sep 22 15:33:30 minikube kubelet[1154]: Flag --feature-gates has been deprecated, This parameter should be set via the config file specified by the Kubelet's --config flag. See https://kubernetes.io/docs/tasks/administer-cluster/kubelet-config-file/ for more information.
Sep 22 15:33:30 minikube kubelet[1154]: E0922 15:33:30.056728    1154 run.go:72] "command failed" err="failed to load kubelet config file, path: /var/lib/kubelet/config.yaml, error: failed to load Kubelet config file /var/lib/kubelet/config.yaml, error failed to read kubelet config file \"/var/lib/kubelet/config.yaml\", error: open /var/lib/kubelet/config.yaml: no such file or directory"
Sep 22 15:33:30 minikube systemd[1]: kubelet.service: Main process exited, code=exited, status=1/FAILURE
Sep 22 15:33:30 minikube systemd[1]: kubelet.service: Failed with result 'exit-code'.
Sep 22 15:33:30 minikube systemd[1]: Stopped kubelet: The Kubernetes Node Agent.
Sep 22 15:33:30 minikube systemd[1]: Started kubelet: The Kubernetes Node Agent.
Sep 22 15:33:30 minikube kubelet[1183]: Flag --cgroups-per-qos has been deprecated, This parameter should be set via the config file specified by the Kubelet's --config flag. See https://kubernetes.io/docs/tasks/administer-cluster/kubelet-config-file/ for more information.
Sep 22 15:33:30 minikube kubelet[1183]: Flag --enforce-node-allocatable has been deprecated, This parameter should be set via the config file specified by the Kubelet's --config flag. See https://kubernetes.io/docs/tasks/administer-cluster/kubelet-config-file/ for more information.
Sep 22 15:33:30 minikube kubelet[1183]: Flag --feature-gates has been deprecated, This parameter should be set via the config file specified by the Kubelet's --config flag. See https://kubernetes.io/docs/tasks/administer-cluster/kubelet-config-file/ for more information.
Sep 22 15:33:30 minikube kubelet[1183]: I0922 15:33:30.852716    1183 server.go:486] "Kubelet version" kubeletVersion="v1.31.0"
Sep 22 15:33:30 minikube kubelet[1183]: I0922 15:33:30.852829    1183 server.go:488] "Golang settings" GOGC="" GOMAXPROCS="" GOTRACEBACK=""
Sep 22 15:33:30 minikube kubelet[1183]: I0922 15:33:30.853171    1183 server.go:929] "Client rotation is on, will bootstrap in background"
Sep 22 15:33:30 minikube kubelet[1183]: I0922 15:33:30.861436    1183 dynamic_cafile_content.go:160] "Starting controller" name="client-ca-bundle::/var/lib/minikube/certs/ca.crt"
Sep 22 15:33:30 minikube kubelet[1183]: E0922 15:33:30.863517    1183 certificate_manager.go:562] "Unhandled Error" err="kubernetes.io/kube-apiserver-client-kubelet: Failed while requesting a signed certificate from the control plane: cannot create certificate signing request: Post \"https://control-plane.minikube.internal:8443/apis/certificates.k8s.io/v1/certificatesigningrequests\": dial tcp 192.168.49.2:8443: connect: connection refused" logger="UnhandledError"
Sep 22 15:33:30 minikube kubelet[1183]: E0922 15:33:30.868756    1183 log.go:32] "RuntimeConfig from runtime service failed" err="rpc error: code = Unimplemented desc = unknown method RuntimeConfig for service runtime.v1.RuntimeService"
Sep 22 15:33:30 minikube kubelet[1183]: I0922 15:33:30.868831    1183 server.go:1403] "CRI implementation should be updated to support RuntimeConfig when KubeletCgroupDriverFromCRI feature gate has been enabled. Falling back to using cgroupDriver from kubelet config."
Sep 22 15:33:30 minikube kubelet[1183]: I0922 15:33:30.979204    1183 server.go:812] "NoSwap is set due to memorySwapBehavior not specified" memorySwapBehavior="" FailSwapOn=false
Sep 22 15:33:30 minikube kubelet[1183]: I0922 15:33:30.980729    1183 swap_util.go:113] "Swap is on" /proc/swaps contents=<
Sep 22 15:33:30 minikube kubelet[1183]:         Filename                                Type                Size                Used                Priority
Sep 22 15:33:30 minikube kubelet[1183]:         /var/lib/swap                           file                1048572                0                -2
Sep 22 15:33:30 minikube kubelet[1183]:  >
Sep 22 15:33:30 minikube kubelet[1183]: I0922 15:33:30.982393    1183 container_manager_linux.go:269] "Creating Container Manager object based on Node Config" nodeConfig={"NodeName":"minikube","RuntimeCgroupsName":"","SystemCgroupsName":"","KubeletCgroupsName":"","KubeletOOMScoreAdj":-999,"ContainerRuntime":"","CgroupsPerQOS":false,"CgroupRoot":"","CgroupDriver":"cgroupfs","KubeletRootDir":"/var/lib/kubelet","ProtectKernelDefaults":false,"KubeReservedCgroupName":"","SystemReservedCgroupName":"","ReservedSystemCPUs":{},"EnforceNodeAllocatable":{},"KubeReserved":null,"SystemReserved":null,"HardEvictionThresholds":[],"QOSReserved":{},"CPUManagerPolicy":"none","CPUManagerPolicyOptions":null,"TopologyManagerScope":"container","CPUManagerReconcilePeriod":10000000000,"ExperimentalMemoryManagerPolicy":"None","ExperimentalMemoryManagerReservedMemory":null,"PodPidsLimit":-1,"EnforceCPULimits":true,"CPUCFSQuotaPeriod":100000000,"TopologyManagerPolicy":"none","TopologyManagerPolicyOptions":null,"CgroupVersion":2}
Sep 22 15:33:30 minikube kubelet[1183]: I0922 15:33:30.987156    1183 topology_manager.go:138] "Creating topology manager with none policy"
Sep 22 15:33:30 minikube kubelet[1183]: I0922 15:33:30.987214    1183 container_manager_linux.go:300] "Creating device plugin manager"
Sep 22 15:33:30 minikube kubelet[1183]: I0922 15:33:30.991567    1183 state_mem.go:36] "Initialized new in-memory state store"
Sep 22 15:33:31 minikube kubelet[1183]: I0922 15:33:30.993420    1183 kubelet.go:408] "Attempting to sync node with API server"
Sep 22 15:33:31 minikube kubelet[1183]: I0922 15:33:31.004117    1183 kubelet.go:303] "Adding static pod path" path="/etc/kubernetes/manifests"
Sep 22 15:33:31 minikube kubelet[1183]: I0922 15:33:31.004246    1183 kubelet.go:314] "Adding apiserver pod source"
Sep 22 15:33:31 minikube kubelet[1183]: I0922 15:33:31.004340    1183 apiserver.go:42] "Waiting for node sync before watching apiserver pods"
Sep 22 15:33:31 minikube kubelet[1183]: W0922 15:33:31.015738    1183 reflector.go:561] k8s.io/client-go/informers/factory.go:160: failed to list *v1.Node: Get "https://control-plane.minikube.internal:8443/api/v1/nodes?fieldSelector=metadata.name%3Dminikube&limit=500&resourceVersion=0": dial tcp 192.168.49.2:8443: connect: connection refused
Sep 22 15:33:31 minikube kubelet[1183]: E0922 15:33:31.015961    1183 reflector.go:158] "Unhandled Error" err="k8s.io/client-go/informers/factory.go:160: Failed to watch *v1.Node: failed to list *v1.Node: Get \"https://control-plane.minikube.internal:8443/api/v1/nodes?fieldSelector=metadata.name%3Dminikube&limit=500&resourceVersion=0\": dial tcp 192.168.49.2:8443: connect: connection refused" logger="UnhandledError"
Sep 22 15:33:31 minikube kubelet[1183]: W0922 15:33:31.017363    1183 reflector.go:561] k8s.io/client-go/informers/factory.go:160: failed to list *v1.Service: Get "https://control-plane.minikube.internal:8443/api/v1/services?fieldSelector=spec.clusterIP%21%3DNone&limit=500&resourceVersion=0": dial tcp 192.168.49.2:8443: connect: connection refused
Sep 22 15:33:31 minikube kubelet[1183]: E0922 15:33:31.017401    1183 reflector.go:158] "Unhandled Error" err="k8s.io/client-go/informers/factory.go:160: Failed to watch *v1.Service: failed to list *v1.Service: Get \"https://control-plane.minikube.internal:8443/api/v1/services?fieldSelector=spec.clusterIP%21%3DNone&limit=500&resourceVersion=0\": dial tcp 192.168.49.2:8443: connect: connection refused" logger="UnhandledError"
Sep 22 15:33:31 minikube kubelet[1183]: I0922 15:33:31.017549    1183 kuberuntime_manager.go:262] "Container runtime initialized" containerRuntime="cri-o" version="1.24.6" apiVersion="v1"
Sep 22 15:33:31 minikube kubelet[1183]: I0922 15:33:31.027803    1183 kubelet.go:837] "Not starting ClusterTrustBundle informer because we are in static kubelet mode"
Sep 22 15:33:31 minikube kubelet[1183]: W0922 15:33:31.028042    1183 probe.go:272] Flexvolume plugin directory at /usr/libexec/kubernetes/kubelet-plugins/volume/exec/ does not exist. Recreating.
Sep 22 15:33:31 minikube kubelet[1183]: I0922 15:33:31.030903    1183 server.go:1269] "Started kubelet"
Sep 22 15:33:31 minikube kubelet[1183]: E0922 15:33:31.033096    1183 event.go:368] "Unable to write event (may retry after sleeping)" err="Post \"https://control-plane.minikube.internal:8443/api/v1/namespaces/default/events\": dial tcp 192.168.49.2:8443: connect: connection refused" event="&Event{ObjectMeta:{minikube.17f79ad281b48213  default    0 0001-01-01 00:00:00 +0000 UTC <nil> <nil> map[] map[] [] [] []},InvolvedObject:ObjectReference{Kind:Node,Namespace:,Name:minikube,UID:minikube,APIVersion:,ResourceVersion:,FieldPath:,},Reason:Starting,Message:Starting kubelet.,Source:EventSource{Component:kubelet,Host:minikube,},FirstTimestamp:2024-09-22 15:33:31.029774867 +0000 UTC m=+0.586604007,LastTimestamp:2024-09-22 15:33:31.029774867 +0000 UTC m=+0.586604007,Count:1,Type:Normal,EventTime:0001-01-01 00:00:00 +0000 UTC,Series:nil,Action:,Related:nil,ReportingController:kubelet,ReportingInstance:minikube,}"
Sep 22 15:33:31 minikube kubelet[1183]: I0922 15:33:31.033537    1183 ratelimit.go:55] "Setting rate limiting for endpoint" service="podresources" qps=100 burstTokens=10
Sep 22 15:33:31 minikube kubelet[1183]: I0922 15:33:31.033994    1183 fs_resource_analyzer.go:67] "Starting FS ResourceAnalyzer"
Sep 22 15:33:31 minikube kubelet[1183]: I0922 15:33:31.034026    1183 server.go:236] "Starting to serve the podresources API" endpoint="unix:/var/lib/kubelet/pod-resources/kubelet.sock"
Sep 22 15:33:31 minikube kubelet[1183]: I0922 15:33:31.034837    1183 server.go:163] "Starting to listen" address="0.0.0.0" port=10250
Sep 22 15:33:31 minikube kubelet[1183]: I0922 15:33:31.036210    1183 dynamic_serving_content.go:135] "Starting controller" name="kubelet-server-cert-files::/var/lib/kubelet/pki/kubelet.crt::/var/lib/kubelet/pki/kubelet.key"
Sep 22 15:33:31 minikube kubelet[1183]: I0922 15:33:31.037027    1183 server.go:460] "Adding debug handlers to kubelet server"
Sep 22 15:33:31 minikube kubelet[1183]: I0922 15:33:31.037695    1183 volume_manager.go:289] "Starting Kubelet Volume Manager"
Sep 22 15:33:31 minikube kubelet[1183]: E0922 15:33:31.038173    1183 kubelet_node_status.go:453] "Error getting the current node from lister" err="node \"minikube\" not found"
Sep 22 15:33:31 minikube kubelet[1183]: I0922 15:33:31.039775    1183 desired_state_of_world_populator.go:146] "Desired state populator starts to run"
Sep 22 15:33:31 minikube kubelet[1183]: I0922 15:33:31.040044    1183 reconciler.go:26] "Reconciler: start to sync state"
Sep 22 15:33:31 minikube kubelet[1183]: E0922 15:33:31.041544    1183 controller.go:145] "Failed to ensure lease exists, will retry" err="Get \"https://control-plane.minikube.internal:8443/apis/coordination.k8s.io/v1/namespaces/kube-node-lease/leases/minikube?timeout=10s\": dial tcp 192.168.49.2:8443: connect: connection refused" interval="200ms"
Sep 22 15:33:31 minikube kubelet[1183]: W0922 15:33:31.042618    1183 reflector.go:561] k8s.io/client-go/informers/factory.go:160: failed to list *v1.CSIDriver: Get "https://control-plane.minikube.internal:8443/apis/storage.k8s.io/v1/csidrivers?limit=500&resourceVersion=0": dial tcp 192.168.49.2:8443: connect: connection refused
Sep 22 15:33:31 minikube kubelet[1183]: E0922 15:33:31.042859    1183 reflector.go:158] "Unhandled Error" err="k8s.io/client-go/informers/factory.go:160: Failed to watch *v1.CSIDriver: failed to list *v1.CSIDriver: Get \"https://control-plane.minikube.internal:8443/apis/storage.k8s.io/v1/csidrivers?limit=500&resourceVersion=0\": dial tcp 192.168.49.2:8443: connect: connection refused" logger="UnhandledError"
Sep 22 15:33:31 minikube kubelet[1183]: I0922 15:33:31.043668    1183 factory.go:221] Registration of the systemd container factory successfully
Sep 22 15:33:31 minikube kubelet[1183]: I0922 15:33:31.044529    1183 factory.go:221] Registration of the crio container factory successfully
Sep 22 15:33:31 minikube kubelet[1183]: I0922 15:33:31.044609    1183 factory.go:219] Registration of the containerd container factory failed: unable to create containerd client: containerd: cannot unix dial containerd api service: dial unix /run/containerd/containerd.sock: connect: no such file or directory
Sep 22 15:33:31 minikube kubelet[1183]: I0922 15:33:31.054877    1183 cpu_manager.go:214] "Starting CPU manager" policy="none"
Sep 22 15:33:31 minikube kubelet[1183]: I0922 15:33:31.055012    1183 cpu_manager.go:215] "Reconciling" reconcilePeriod="10s"
Sep 22 15:33:31 minikube kubelet[1183]: I0922 15:33:31.055091    1183 state_mem.go:36] "Initialized new in-memory state store"
Sep 22 15:33:31 minikube kubelet[1183]: I0922 15:33:31.059276    1183 policy_none.go:49] "None policy: Start"
Sep 22 15:33:31 minikube kubelet[1183]: I0922 15:33:31.063251    1183 memory_manager.go:170] "Starting memorymanager" policy="None"
Sep 22 15:33:31 minikube kubelet[1183]: I0922 15:33:31.063363    1183 state_mem.go:35] "Initializing new in-memory state store"
Sep 22 15:33:31 minikube kubelet[1183]: I0922 15:33:31.067420    1183 kubelet_network_linux.go:50] "Initialized iptables rules." protocol="IPv4"
Sep 22 15:33:31 minikube kubelet[1183]: I0922 15:33:31.068249    1183 manager.go:510] "Failed to read data from checkpoint" checkpoint="kubelet_internal_checkpoint" err="checkpoint is not found"
Sep 22 15:33:31 minikube kubelet[1183]: I0922 15:33:31.068569    1183 eviction_manager.go:189] "Eviction manager: starting control loop"
Sep 22 15:33:31 minikube kubelet[1183]: I0922 15:33:31.068683    1183 container_log_manager.go:189] "Initializing container log rotate workers" workers=1 monitorPeriod="10s"
Sep 22 15:33:31 minikube kubelet[1183]: I0922 15:33:31.069671    1183 plugin_manager.go:118] "Starting Kubelet Plugin Manager"
Sep 22 15:33:31 minikube kubelet[1183]: E0922 15:33:31.070513    1183 eviction_manager.go:257] "Eviction manager: failed to get HasDedicatedImageFs" err="missing image stats: &ImageFsInfoResponse{ImageFilesystems:[]*FilesystemUsage{&FilesystemUsage{Timestamp:1727019211070211811,FsId:&FilesystemIdentifier{Mountpoint:/var/lib/containers/storage/overlay-images,},UsedBytes:&UInt64Value{Value:125204,},InodesUsed:&UInt64Value{Value:57,},},},ContainerFilesystems:[]*FilesystemUsage{},}"
Sep 22 15:33:31 minikube kubelet[1183]: E0922 15:33:31.070591    1183 eviction_manager.go:212] "Eviction manager: failed to synchronize" err="eviction manager: failed to get HasDedicatedImageFs: missing image stats: &ImageFsInfoResponse{ImageFilesystems:[]*FilesystemUsage{&FilesystemUsage{Timestamp:1727019211070211811,FsId:&FilesystemIdentifier{Mountpoint:/var/lib/containers/storage/overlay-images,},UsedBytes:&UInt64Value{Value:125204,},InodesUsed:&UInt64Value{Value:57,},},},ContainerFilesystems:[]*FilesystemUsage{},}"
Sep 22 15:33:31 minikube kubelet[1183]: I0922 15:33:31.072521    1183 kubelet_network_linux.go:50] "Initialized iptables rules." protocol="IPv6"
Sep 22 15:33:31 minikube kubelet[1183]: I0922 15:33:31.072649    1183 status_manager.go:217] "Starting to sync pod status with apiserver"
Sep 22 15:33:31 minikube kubelet[1183]: I0922 15:33:31.072713    1183 kubelet.go:2321] "Starting kubelet main sync loop"
Sep 22 15:33:31 minikube kubelet[1183]: E0922 15:33:31.072808    1183 kubelet.go:2345] "Skipping pod synchronization" err="PLEG is not healthy: pleg has yet to be successful"
Sep 22 15:33:31 minikube kubelet[1183]: W0922 15:33:31.073989    1183 reflector.go:561] k8s.io/client-go/informers/factory.go:160: failed to list *v1.RuntimeClass: Get "https://control-plane.minikube.internal:8443/apis/node.k8s.io/v1/runtimeclasses?limit=500&resourceVersion=0": dial tcp 192.168.49.2:8443: connect: connection refused
Sep 22 15:33:31 minikube kubelet[1183]: E0922 15:33:31.074081    1183 reflector.go:158] "Unhandled Error" err="k8s.io/client-go/informers/factory.go:160: Failed to watch *v1.RuntimeClass: failed to list *v1.RuntimeClass: Get \"https://control-plane.minikube.internal:8443/apis/node.k8s.io/v1/runtimeclasses?limit=500&resourceVersion=0\": dial tcp 192.168.49.2:8443: connect: connection refused" logger="UnhandledError"
Sep 22 15:33:31 minikube kubelet[1183]: I0922 15:33:31.171210    1183 kubelet_node_status.go:72] "Attempting to register node" node="minikube"
Sep 22 15:33:31 minikube kubelet[1183]: E0922 15:33:31.171959    1183 kubelet_node_status.go:95] "Unable to register node with API server" err="Post \"https://control-plane.minikube.internal:8443/api/v1/nodes\": dial tcp 192.168.49.2:8443: connect: connection refused" node="minikube"
Sep 22 15:33:31 minikube kubelet[1183]: E0922 15:33:31.246630    1183 controller.go:145] "Failed to ensure lease exists, will retry" err="Get \"https://control-plane.minikube.internal:8443/apis/coordination.k8s.io/v1/namespaces/kube-node-lease/leases/minikube?timeout=10s\": dial tcp 192.168.49.2:8443: connect: connection refused" interval="400ms"
Sep 22 15:33:31 minikube kubelet[1183]: I0922 15:33:31.350676    1183 reconciler_common.go:245] "operationExecutor.VerifyControllerAttachedVolume started for volume \"k8s-certs\" (UniqueName: \"kubernetes.io/host-path/9e315b3a91fa9f6f7463439d9dac1a56-k8s-certs\") pod \"kube-apiserver-minikube\" (UID: \"9e315b3a91fa9f6f7463439d9dac1a56\") " pod="kube-system/kube-apiserver-minikube"
Sep 22 15:33:31 minikube kubelet[1183]: I0922 15:33:31.350735    1183 reconciler_common.go:245] "operationExecutor.VerifyControllerAttachedVolume started for volume \"ca-certs\" (UniqueName: \"kubernetes.io/host-path/40f5f661ab65f2e4bfe41ac2993c01de-ca-certs\") pod \"kube-controller-manager-minikube\" (UID: \"40f5f661ab65f2e4bfe41ac2993c01de\") " pod="kube-system/kube-controller-manager-minikube"
Sep 22 15:33:31 minikube kubelet[1183]: I0922 15:33:31.350755    1183 reconciler_common.go:245] "operationExecutor.VerifyControllerAttachedVolume started for volume \"kubeconfig\" (UniqueName: \"kubernetes.io/host-path/40f5f661ab65f2e4bfe41ac2993c01de-kubeconfig\") pod \"kube-controller-manager-minikube\" (UID: \"40f5f661ab65f2e4bfe41ac2993c01de\") " pod="kube-system/kube-controller-manager-minikube"
Sep 22 15:33:31 minikube kubelet[1183]: I0922 15:33:31.350771    1183 reconciler_common.go:245] "operationExecutor.VerifyControllerAttachedVolume started for volume \"usr-local-share-ca-certificates\" (UniqueName: \"kubernetes.io/host-path/40f5f661ab65f2e4bfe41ac2993c01de-usr-local-share-ca-certificates\") pod \"kube-controller-manager-minikube\" (UID: \"40f5f661ab65f2e4bfe41ac2993c01de\") " pod="kube-system/kube-controller-manager-minikube"
Sep 22 15:33:31 minikube kubelet[1183]: I0922 15:33:31.350785    1183 reconciler_common.go:245] "operationExecutor.VerifyControllerAttachedVolume started for volume \"kubeconfig\" (UniqueName: \"kubernetes.io/host-path/e039200acb850c82bb901653cc38ff6e-kubeconfig\") pod \"kube-scheduler-minikube\" (UID: \"e039200acb850c82bb901653cc38ff6e\") " pod="kube-system/kube-scheduler-minikube"
Sep 22 15:33:31 minikube kubelet[1183]: I0922 15:33:31.350797    1183 reconciler_common.go:245] "operationExecutor.VerifyControllerAttachedVolume started for volume \"ca-certs\" (UniqueName: \"kubernetes.io/host-path/9e315b3a91fa9f6f7463439d9dac1a56-ca-certs\") pod \"kube-apiserver-minikube\" (UID: \"9e315b3a91fa9f6f7463439d9dac1a56\") " pod="kube-system/kube-apiserver-minikube"
Sep 22 15:33:31 minikube kubelet[1183]: I0922 15:33:31.350809    1183 reconciler_common.go:245] "operationExecutor.VerifyControllerAttachedVolume started for volume \"flexvolume-dir\" (UniqueName: \"kubernetes.io/host-path/40f5f661ab65f2e4bfe41ac2993c01de-flexvolume-dir\") pod \"kube-controller-manager-minikube\" (UID: \"40f5f661ab65f2e4bfe41ac2993c01de\") " pod="kube-system/kube-controller-manager-minikube"
Sep 22 15:33:31 minikube kubelet[1183]: I0922 15:33:31.350820    1183 reconciler_common.go:245] "operationExecutor.VerifyControllerAttachedVolume started for volume \"etc-ca-certificates\" (UniqueName: \"kubernetes.io/host-path/9e315b3a91fa9f6f7463439d9dac1a56-etc-ca-certificates\") pod \"kube-apiserver-minikube\" (UID: \"9e315b3a91fa9f6f7463439d9dac1a56\") " pod="kube-system/kube-apiserver-minikube"
Sep 22 15:33:31 minikube kubelet[1183]: I0922 15:33:31.350965    1183 reconciler_common.go:245] "operationExecutor.VerifyControllerAttachedVolume started for volume \"usr-share-ca-certificates\" (UniqueName: \"kubernetes.io/host-path/9e315b3a91fa9f6f7463439d9dac1a56-usr-share-ca-certificates\") pod \"kube-apiserver-minikube\" (UID: \"9e315b3a91fa9f6f7463439d9dac1a56\") " pod="kube-system/kube-apiserver-minikube"
Sep 22 15:33:31 minikube kubelet[1183]: I0922 15:33:31.350984    1183 reconciler_common.go:245] "operationExecutor.VerifyControllerAttachedVolume started for volume \"usr-share-ca-certificates\" (UniqueName: \"kubernetes.io/host-path/40f5f661ab65f2e4bfe41ac2993c01de-usr-share-ca-certificates\") pod \"kube-controller-manager-minikube\" (UID: \"40f5f661ab65f2e4bfe41ac2993c01de\") " pod="kube-system/kube-controller-manager-minikube"
Sep 22 15:33:31 minikube kubelet[1183]: I0922 15:33:31.350997    1183 reconciler_common.go:245] "operationExecutor.VerifyControllerAttachedVolume started for volume \"etcd-data\" (UniqueName: \"kubernetes.io/host-path/a5363f4f31e043bdae3c93aca4991903-etcd-data\") pod \"etcd-minikube\" (UID: \"a5363f4f31e043bdae3c93aca4991903\") " pod="kube-system/etcd-minikube"
Sep 22 15:33:31 minikube kubelet[1183]: I0922 15:33:31.351010    1183 reconciler_common.go:245] "operationExecutor.VerifyControllerAttachedVolume started for volume \"usr-local-share-ca-certificates\" (UniqueName: \"kubernetes.io/host-path/9e315b3a91fa9f6f7463439d9dac1a56-usr-local-share-ca-certificates\") pod \"kube-apiserver-minikube\" (UID: \"9e315b3a91fa9f6f7463439d9dac1a56\") " pod="kube-system/kube-apiserver-minikube"
Sep 22 15:33:31 minikube kubelet[1183]: I0922 15:33:31.351024    1183 reconciler_common.go:245] "operationExecutor.VerifyControllerAttachedVolume started for volume \"etc-ca-certificates\" (UniqueName: \"kubernetes.io/host-path/40f5f661ab65f2e4bfe41ac2993c01de-etc-ca-certificates\") pod \"kube-controller-manager-minikube\" (UID: \"40f5f661ab65f2e4bfe41ac2993c01de\") " pod="kube-system/kube-controller-manager-minikube"
Sep 22 15:33:31 minikube kubelet[1183]: I0922 15:33:31.351035    1183 reconciler_common.go:245] "operationExecutor.VerifyControllerAttachedVolume started for volume \"k8s-certs\" (UniqueName: \"kubernetes.io/host-path/40f5f661ab65f2e4bfe41ac2993c01de-k8s-certs\") pod \"kube-controller-manager-minikube\" (UID: \"40f5f661ab65f2e4bfe41ac2993c01de\") " pod="kube-system/kube-controller-manager-minikube"
Sep 22 15:33:31 minikube kubelet[1183]: I0922 15:33:31.351099    1183 reconciler_common.go:245] "operationExecutor.VerifyControllerAttachedVolume started for volume \"etcd-certs\" (UniqueName: \"kubernetes.io/host-path/a5363f4f31e043bdae3c93aca4991903-etcd-certs\") pod \"etcd-minikube\" (UID: \"a5363f4f31e043bdae3c93aca4991903\") " pod="kube-system/etcd-minikube"
Sep 22 15:33:31 minikube kubelet[1183]: I0922 15:33:31.374079    1183 kubelet_node_status.go:72] "Attempting to register node" node="minikube"
Sep 22 15:33:31 minikube kubelet[1183]: E0922 15:33:31.374520    1183 kubelet_node_status.go:95] "Unable to register node with API server" err="Post \"https://control-plane.minikube.internal:8443/api/v1/nodes\": dial tcp 192.168.49.2:8443: connect: connection refused" node="minikube"
Sep 22 15:33:31 minikube kubelet[1183]: E0922 15:33:31.650349    1183 controller.go:145] "Failed to ensure lease exists, will retry" err="Get \"https://control-plane.minikube.internal:8443/apis/coordination.k8s.io/v1/namespaces/kube-node-lease/leases/minikube?timeout=10s\": dial tcp 192.168.49.2:8443: connect: connection refused" interval="800ms"
Sep 22 15:33:31 minikube kubelet[1183]: I0922 15:33:31.780947    1183 kubelet_node_status.go:72] "Attempting to register node" node="minikube"
Sep 22 15:33:31 minikube kubelet[1183]: E0922 15:33:31.781329    1183 kubelet_node_status.go:95] "Unable to register node with API server" err="Post \"https://control-plane.minikube.internal:8443/api/v1/nodes\": dial tcp 192.168.49.2:8443: connect: connection refused" node="minikube"
Sep 22 15:33:32 minikube kubelet[1183]: I0922 15:33:32.631847    1183 kubelet_node_status.go:72] "Attempting to register node" node="minikube"
Sep 22 15:33:35 minikube kubelet[1183]: E0922 15:33:35.305501    1183 nodelease.go:49] "Failed to get node when trying to set owner ref to the node lease" err="nodes \"minikube\" not found" node="minikube"
Sep 22 15:33:35 minikube kubelet[1183]: I0922 15:33:35.390639    1183 kubelet_node_status.go:75] "Successfully registered node" node="minikube"
Sep 22 15:33:36 minikube kubelet[1183]: I0922 15:33:36.034764    1183 apiserver.go:52] "Watching apiserver"
Sep 22 15:33:36 minikube kubelet[1183]: I0922 15:33:36.039690    1183 desired_state_of_world_populator.go:154] "Finished populating initial desired state of world"
Sep 22 15:33:38 minikube systemd[1]: Stopping kubelet: The Kubernetes Node Agent...
Sep 22 15:33:38 minikube kubelet[1183]: I0922 15:33:38.020576    1183 dynamic_cafile_content.go:174] "Shutting down controller" name="client-ca-bundle::/var/lib/minikube/certs/ca.crt"
Sep 22 15:33:38 minikube systemd[1]: kubelet.service: Deactivated successfully.
Sep 22 15:33:38 minikube systemd[1]: Stopped kubelet: The Kubernetes Node Agent.
Sep 22 15:33:38 minikube systemd[1]: kubelet.service: Consumed 1.488s CPU time.
Sep 22 15:33:38 minikube systemd[1]: Started kubelet: The Kubernetes Node Agent.
Sep 22 15:33:38 minikube kubelet[1413]: Flag --cgroups-per-qos has been deprecated, This parameter should be set via the config file specified by the Kubelet's --config flag. See https://kubernetes.io/docs/tasks/administer-cluster/kubelet-config-file/ for more information.
Sep 22 15:33:38 minikube kubelet[1413]: Flag --enforce-node-allocatable has been deprecated, This parameter should be set via the config file specified by the Kubelet's --config flag. See https://kubernetes.io/docs/tasks/administer-cluster/kubelet-config-file/ for more information.
Sep 22 15:33:38 minikube kubelet[1413]: Flag --feature-gates has been deprecated, This parameter should be set via the config file specified by the Kubelet's --config flag. See https://kubernetes.io/docs/tasks/administer-cluster/kubelet-config-file/ for more information.
Sep 22 15:33:38 minikube kubelet[1413]: I0922 15:33:38.183278    1413 server.go:486] "Kubelet version" kubeletVersion="v1.31.0"
Sep 22 15:33:38 minikube kubelet[1413]: I0922 15:33:38.183344    1413 server.go:488] "Golang settings" GOGC="" GOMAXPROCS="" GOTRACEBACK=""
Sep 22 15:33:38 minikube kubelet[1413]: I0922 15:33:38.183723    1413 server.go:929] "Client rotation is on, will bootstrap in background"
Sep 22 15:33:38 minikube kubelet[1413]: I0922 15:33:38.185217    1413 certificate_store.go:130] Loading cert/key pair from "/var/lib/kubelet/pki/kubelet-client-current.pem".
Sep 22 15:33:38 minikube kubelet[1413]: I0922 15:33:38.188480    1413 dynamic_cafile_content.go:160] "Starting controller" name="client-ca-bundle::/var/lib/minikube/certs/ca.crt"
Sep 22 15:33:38 minikube kubelet[1413]: E0922 15:33:38.193177    1413 log.go:32] "RuntimeConfig from runtime service failed" err="rpc error: code = Unimplemented desc = unknown method RuntimeConfig for service runtime.v1.RuntimeService"
Sep 22 15:33:38 minikube kubelet[1413]: I0922 15:33:38.193209    1413 server.go:1403] "CRI implementation should be updated to support RuntimeConfig when KubeletCgroupDriverFromCRI feature gate has been enabled. Falling back to using cgroupDriver from kubelet config."
Sep 22 15:33:38 minikube kubelet[1413]: I0922 15:33:38.215294    1413 server.go:812] "NoSwap is set due to memorySwapBehavior not specified" memorySwapBehavior="" FailSwapOn=false
Sep 22 15:33:38 minikube kubelet[1413]: I0922 15:33:38.215506    1413 swap_util.go:113] "Swap is on" /proc/swaps contents=<
Sep 22 15:33:38 minikube kubelet[1413]:         Filename                                Type                Size                Used                Priority
Sep 22 15:33:38 minikube kubelet[1413]:         /var/lib/swap                           file                1048572                0                -2
Sep 22 15:33:38 minikube kubelet[1413]:  >
Sep 22 15:33:38 minikube kubelet[1413]: I0922 15:33:38.215712    1413 container_manager_linux.go:269] "Creating Container Manager object based on Node Config" nodeConfig={"NodeName":"minikube","RuntimeCgroupsName":"","SystemCgroupsName":"","KubeletCgroupsName":"","KubeletOOMScoreAdj":-999,"ContainerRuntime":"","CgroupsPerQOS":false,"CgroupRoot":"","CgroupDriver":"cgroupfs","KubeletRootDir":"/var/lib/kubelet","ProtectKernelDefaults":false,"KubeReservedCgroupName":"","SystemReservedCgroupName":"","ReservedSystemCPUs":{},"EnforceNodeAllocatable":{},"KubeReserved":null,"SystemReserved":null,"HardEvictionThresholds":[],"QOSReserved":{},"CPUManagerPolicy":"none","CPUManagerPolicyOptions":null,"TopologyManagerScope":"container","CPUManagerReconcilePeriod":10000000000,"ExperimentalMemoryManagerPolicy":"None","ExperimentalMemoryManagerReservedMemory":null,"PodPidsLimit":-1,"EnforceCPULimits":true,"CPUCFSQuotaPeriod":100000000,"TopologyManagerPolicy":"none","TopologyManagerPolicyOptions":null,"CgroupVersion":2}
Sep 22 15:33:38 minikube kubelet[1413]: I0922 15:33:38.215863    1413 topology_manager.go:138] "Creating topology manager with none policy"
Sep 22 15:33:38 minikube kubelet[1413]: I0922 15:33:38.215871    1413 container_manager_linux.go:300] "Creating device plugin manager"
Sep 22 15:33:38 minikube kubelet[1413]: I0922 15:33:38.215904    1413 state_mem.go:36] "Initialized new in-memory state store"
Sep 22 15:33:38 minikube kubelet[1413]: I0922 15:33:38.216028    1413 kubelet.go:408] "Attempting to sync node with API server"
Sep 22 15:33:38 minikube kubelet[1413]: I0922 15:33:38.216040    1413 kubelet.go:303] "Adding static pod path" path="/etc/kubernetes/manifests"
Sep 22 15:33:38 minikube kubelet[1413]: I0922 15:33:38.216064    1413 kubelet.go:314] "Adding apiserver pod source"
Sep 22 15:33:38 minikube kubelet[1413]: I0922 15:33:38.216076    1413 apiserver.go:42] "Waiting for node sync before watching apiserver pods"
Sep 22 15:33:38 minikube kubelet[1413]: I0922 15:33:38.218295    1413 kuberuntime_manager.go:262] "Container runtime initialized" containerRuntime="cri-o" version="1.24.6" apiVersion="v1"
Sep 22 15:33:38 minikube kubelet[1413]: I0922 15:33:38.218762    1413 kubelet.go:837] "Not starting ClusterTrustBundle informer because we are in static kubelet mode"
Sep 22 15:33:38 minikube kubelet[1413]: I0922 15:33:38.219251    1413 server.go:1269] "Started kubelet"
Sep 22 15:33:38 minikube kubelet[1413]: I0922 15:33:38.226229    1413 server.go:163] "Starting to listen" address="0.0.0.0" port=10250
Sep 22 15:33:38 minikube kubelet[1413]: I0922 15:33:38.233769    1413 ratelimit.go:55] "Setting rate limiting for endpoint" service="podresources" qps=100 burstTokens=10
Sep 22 15:33:38 minikube kubelet[1413]: I0922 15:33:38.234522    1413 server.go:236] "Starting to serve the podresources API" endpoint="unix:/var/lib/kubelet/pod-resources/kubelet.sock"
Sep 22 15:33:38 minikube kubelet[1413]: I0922 15:33:38.247107    1413 server.go:460] "Adding debug handlers to kubelet server"
Sep 22 15:33:38 minikube kubelet[1413]: I0922 15:33:38.293363    1413 fs_resource_analyzer.go:67] "Starting FS ResourceAnalyzer"
Sep 22 15:33:38 minikube kubelet[1413]: I0922 15:33:38.294042    1413 dynamic_serving_content.go:135] "Starting controller" name="kubelet-server-cert-files::/var/lib/kubelet/pki/kubelet.crt::/var/lib/kubelet/pki/kubelet.key"
Sep 22 15:33:38 minikube kubelet[1413]: E0922 15:33:38.298267    1413 kubelet_node_status.go:453] "Error getting the current node from lister" err="node \"minikube\" not found"
Sep 22 15:33:38 minikube kubelet[1413]: I0922 15:33:38.298471    1413 volume_manager.go:289] "Starting Kubelet Volume Manager"
Sep 22 15:33:38 minikube kubelet[1413]: I0922 15:33:38.298774    1413 desired_state_of_world_populator.go:146] "Desired state populator starts to run"
Sep 22 15:33:38 minikube kubelet[1413]: I0922 15:33:38.299059    1413 reconciler.go:26] "Reconciler: start to sync state"
Sep 22 15:33:38 minikube kubelet[1413]: I0922 15:33:38.301952    1413 factory.go:221] Registration of the crio container factory successfully
Sep 22 15:33:38 minikube kubelet[1413]: I0922 15:33:38.302041    1413 factory.go:219] Registration of the containerd container factory failed: unable to create containerd client: containerd: cannot unix dial containerd api service: dial unix /run/containerd/containerd.sock: connect: no such file or directory
Sep 22 15:33:38 minikube kubelet[1413]: I0922 15:33:38.302052    1413 factory.go:221] Registration of the systemd container factory successfully
Sep 22 15:33:38 minikube kubelet[1413]: I0922 15:33:38.330327    1413 cpu_manager.go:214] "Starting CPU manager" policy="none"
Sep 22 15:33:38 minikube kubelet[1413]: I0922 15:33:38.330343    1413 cpu_manager.go:215] "Reconciling" reconcilePeriod="10s"
Sep 22 15:33:38 minikube kubelet[1413]: I0922 15:33:38.330360    1413 state_mem.go:36] "Initialized new in-memory state store"
Sep 22 15:33:38 minikube kubelet[1413]: I0922 15:33:38.330486    1413 state_mem.go:88] "Updated default CPUSet" cpuSet=""
Sep 22 15:33:38 minikube kubelet[1413]: I0922 15:33:38.330495    1413 state_mem.go:96] "Updated CPUSet assignments" assignments={}
Sep 22 15:33:38 minikube kubelet[1413]: I0922 15:33:38.330511    1413 policy_none.go:49] "None policy: Start"
Sep 22 15:33:38 minikube kubelet[1413]: I0922 15:33:38.331213    1413 memory_manager.go:170] "Starting memorymanager" policy="None"
Sep 22 15:33:38 minikube kubelet[1413]: I0922 15:33:38.331265    1413 state_mem.go:35] "Initializing new in-memory state store"
Sep 22 15:33:38 minikube kubelet[1413]: I0922 15:33:38.331515    1413 state_mem.go:75] "Updated machine memory state"
Sep 22 15:33:38 minikube kubelet[1413]: I0922 15:33:38.332673    1413 manager.go:510] "Failed to read data from checkpoint" checkpoint="kubelet_internal_checkpoint" err="checkpoint is not found"
Sep 22 15:33:38 minikube kubelet[1413]: I0922 15:33:38.332849    1413 eviction_manager.go:189] "Eviction manager: starting control loop"
Sep 22 15:33:38 minikube kubelet[1413]: I0922 15:33:38.332904    1413 container_log_manager.go:189] "Initializing container log rotate workers" workers=1 monitorPeriod="10s"
Sep 22 15:33:38 minikube kubelet[1413]: I0922 15:33:38.333352    1413 plugin_manager.go:118] "Starting Kubelet Plugin Manager"
Sep 22 15:33:38 minikube kubelet[1413]: E0922 15:33:38.335043    1413 eviction_manager.go:257] "Eviction manager: failed to get HasDedicatedImageFs" err="missing image stats: &ImageFsInfoResponse{ImageFilesystems:[]*FilesystemUsage{&FilesystemUsage{Timestamp:1727019218334565494,FsId:&FilesystemIdentifier{Mountpoint:/var/lib/containers/storage/overlay-images,},UsedBytes:&UInt64Value{Value:125204,},InodesUsed:&UInt64Value{Value:57,},},},ContainerFilesystems:[]*FilesystemUsage{},}"
Sep 22 15:33:38 minikube kubelet[1413]: E0922 15:33:38.335108    1413 eviction_manager.go:212] "Eviction manager: failed to synchronize" err="eviction manager: failed to get HasDedicatedImageFs: missing image stats: &ImageFsInfoResponse{ImageFilesystems:[]*FilesystemUsage{&FilesystemUsage{Timestamp:1727019218334565494,FsId:&FilesystemIdentifier{Mountpoint:/var/lib/containers/storage/overlay-images,},UsedBytes:&UInt64Value{Value:125204,},InodesUsed:&UInt64Value{Value:57,},},},ContainerFilesystems:[]*FilesystemUsage{},}"
Sep 22 15:33:38 minikube kubelet[1413]: I0922 15:33:38.337725    1413 kubelet_network_linux.go:50] "Initialized iptables rules." protocol="IPv4"
Sep 22 15:33:38 minikube kubelet[1413]: I0922 15:33:38.340694    1413 kubelet_network_linux.go:50] "Initialized iptables rules." protocol="IPv6"
Sep 22 15:33:38 minikube kubelet[1413]: I0922 15:33:38.340745    1413 status_manager.go:217] "Starting to sync pod status with apiserver"
Sep 22 15:33:38 minikube kubelet[1413]: I0922 15:33:38.340769    1413 kubelet.go:2321] "Starting kubelet main sync loop"
Sep 22 15:33:38 minikube kubelet[1413]: E0922 15:33:38.340805    1413 kubelet.go:2345] "Skipping pod synchronization" err="PLEG is not healthy: pleg has yet to be successful"
Sep 22 15:33:38 minikube kubelet[1413]: I0922 15:33:38.456634    1413 kubelet_node_status.go:72] "Attempting to register node" node="minikube"
Sep 22 15:33:38 minikube kubelet[1413]: I0922 15:33:38.478370    1413 kubelet_node_status.go:111] "Node was previously registered" node="minikube"
Sep 22 15:33:38 minikube kubelet[1413]: I0922 15:33:38.478438    1413 kubelet_node_status.go:75] "Successfully registered node" node="minikube"
Sep 22 15:33:38 minikube kubelet[1413]: I0922 15:33:38.601675    1413 reconciler_common.go:245] "operationExecutor.VerifyControllerAttachedVolume started for volume \"etcd-data\" (UniqueName: \"kubernetes.io/host-path/a5363f4f31e043bdae3c93aca4991903-etcd-data\") pod \"etcd-minikube\" (UID: \"a5363f4f31e043bdae3c93aca4991903\") " pod="kube-system/etcd-minikube"
Sep 22 15:33:38 minikube kubelet[1413]: I0922 15:33:38.601736    1413 reconciler_common.go:245] "operationExecutor.VerifyControllerAttachedVolume started for volume \"ca-certs\" (UniqueName: \"kubernetes.io/host-path/40f5f661ab65f2e4bfe41ac2993c01de-ca-certs\") pod \"kube-controller-manager-minikube\" (UID: \"40f5f661ab65f2e4bfe41ac2993c01de\") " pod="kube-system/kube-controller-manager-minikube"
Sep 22 15:33:38 minikube kubelet[1413]: I0922 15:33:38.602019    1413 reconciler_common.go:245] "operationExecutor.VerifyControllerAttachedVolume started for volume \"flexvolume-dir\" (UniqueName: \"kubernetes.io/host-path/40f5f661ab65f2e4bfe41ac2993c01de-flexvolume-dir\") pod \"kube-controller-manager-minikube\" (UID: \"40f5f661ab65f2e4bfe41ac2993c01de\") " pod="kube-system/kube-controller-manager-minikube"
Sep 22 15:33:38 minikube kubelet[1413]: I0922 15:33:38.602074    1413 reconciler_common.go:245] "operationExecutor.VerifyControllerAttachedVolume started for volume \"etcd-certs\" (UniqueName: \"kubernetes.io/host-path/a5363f4f31e043bdae3c93aca4991903-etcd-certs\") pod \"etcd-minikube\" (UID: \"a5363f4f31e043bdae3c93aca4991903\") " pod="kube-system/etcd-minikube"
Sep 22 15:33:38 minikube kubelet[1413]: I0922 15:33:38.602090    1413 reconciler_common.go:245] "operationExecutor.VerifyControllerAttachedVolume started for volume \"k8s-certs\" (UniqueName: \"kubernetes.io/host-path/40f5f661ab65f2e4bfe41ac2993c01de-k8s-certs\") pod \"kube-controller-manager-minikube\" (UID: \"40f5f661ab65f2e4bfe41ac2993c01de\") " pod="kube-system/kube-controller-manager-minikube"
Sep 22 15:33:38 minikube kubelet[1413]: I0922 15:33:38.602102    1413 reconciler_common.go:245] "operationExecutor.VerifyControllerAttachedVolume started for volume \"kubeconfig\" (UniqueName: \"kubernetes.io/host-path/e039200acb850c82bb901653cc38ff6e-kubeconfig\") pod \"kube-scheduler-minikube\" (UID: \"e039200acb850c82bb901653cc38ff6e\") " pod="kube-system/kube-scheduler-minikube"
Sep 22 15:33:38 minikube kubelet[1413]: I0922 15:33:38.602119    1413 reconciler_common.go:245] "operationExecutor.VerifyControllerAttachedVolume started for volume \"usr-local-share-ca-certificates\" (UniqueName: \"kubernetes.io/host-path/40f5f661ab65f2e4bfe41ac2993c01de-usr-local-share-ca-certificates\") pod \"kube-controller-manager-minikube\" (UID: \"40f5f661ab65f2e4bfe41ac2993c01de\") " pod="kube-system/kube-controller-manager-minikube"
Sep 22 15:33:38 minikube kubelet[1413]: I0922 15:33:38.602134    1413 reconciler_common.go:245] "operationExecutor.VerifyControllerAttachedVolume started for volume \"usr-share-ca-certificates\" (UniqueName: \"kubernetes.io/host-path/40f5f661ab65f2e4bfe41ac2993c01de-usr-share-ca-certificates\") pod \"kube-controller-manager-minikube\" (UID: \"40f5f661ab65f2e4bfe41ac2993c01de\") " pod="kube-system/kube-controller-manager-minikube"
Sep 22 15:33:38 minikube kubelet[1413]: I0922 15:33:38.602147    1413 reconciler_common.go:245] "operationExecutor.VerifyControllerAttachedVolume started for volume \"k8s-certs\" (UniqueName: \"kubernetes.io/host-path/9e315b3a91fa9f6f7463439d9dac1a56-k8s-certs\") pod \"kube-apiserver-minikube\" (UID: \"9e315b3a91fa9f6f7463439d9dac1a56\") " pod="kube-system/kube-apiserver-minikube"
Sep 22 15:33:38 minikube kubelet[1413]: I0922 15:33:38.602158    1413 reconciler_common.go:245] "operationExecutor.VerifyControllerAttachedVolume started for volume \"kubeconfig\" (UniqueName: \"kubernetes.io/host-path/40f5f661ab65f2e4bfe41ac2993c01de-kubeconfig\") pod \"kube-controller-manager-minikube\" (UID: \"40f5f661ab65f2e4bfe41ac2993c01de\") " pod="kube-system/kube-controller-manager-minikube"
Sep 22 15:33:38 minikube kubelet[1413]: I0922 15:33:38.602171    1413 reconciler_common.go:245] "operationExecutor.VerifyControllerAttachedVolume started for volume \"usr-local-share-ca-certificates\" (UniqueName: \"kubernetes.io/host-path/9e315b3a91fa9f6f7463439d9dac1a56-usr-local-share-ca-certificates\") pod \"kube-apiserver-minikube\" (UID: \"9e315b3a91fa9f6f7463439d9dac1a56\") " pod="kube-system/kube-apiserver-minikube"
Sep 22 15:33:38 minikube kubelet[1413]: I0922 15:33:38.602183    1413 reconciler_common.go:245] "operationExecutor.VerifyControllerAttachedVolume started for volume \"usr-share-ca-certificates\" (UniqueName: \"kubernetes.io/host-path/9e315b3a91fa9f6f7463439d9dac1a56-usr-share-ca-certificates\") pod \"kube-apiserver-minikube\" (UID: \"9e315b3a91fa9f6f7463439d9dac1a56\") " pod="kube-system/kube-apiserver-minikube"
Sep 22 15:33:38 minikube kubelet[1413]: I0922 15:33:38.602194    1413 reconciler_common.go:245] "operationExecutor.VerifyControllerAttachedVolume started for volume \"etc-ca-certificates\" (UniqueName: \"kubernetes.io/host-path/40f5f661ab65f2e4bfe41ac2993c01de-etc-ca-certificates\") pod \"kube-controller-manager-minikube\" (UID: \"40f5f661ab65f2e4bfe41ac2993c01de\") " pod="kube-system/kube-controller-manager-minikube"
Sep 22 15:33:38 minikube kubelet[1413]: I0922 15:33:38.602205    1413 reconciler_common.go:245] "operationExecutor.VerifyControllerAttachedVolume started for volume \"ca-certs\" (UniqueName: \"kubernetes.io/host-path/9e315b3a91fa9f6f7463439d9dac1a56-ca-certs\") pod \"kube-apiserver-minikube\" (UID: \"9e315b3a91fa9f6f7463439d9dac1a56\") " pod="kube-system/kube-apiserver-minikube"
Sep 22 15:33:38 minikube kubelet[1413]: I0922 15:33:38.602217    1413 reconciler_common.go:245] "operationExecutor.VerifyControllerAttachedVolume started for volume \"etc-ca-certificates\" (UniqueName: \"kubernetes.io/host-path/9e315b3a91fa9f6f7463439d9dac1a56-etc-ca-certificates\") pod \"kube-apiserver-minikube\" (UID: \"9e315b3a91fa9f6f7463439d9dac1a56\") " pod="kube-system/kube-apiserver-minikube"
Sep 22 15:33:39 minikube kubelet[1413]: I0922 15:33:39.220788    1413 apiserver.go:52] "Watching apiserver"
Sep 22 15:33:39 minikube kubelet[1413]: I0922 15:33:39.299686    1413 desired_state_of_world_populator.go:154] "Finished populating initial desired state of world"
Sep 22 15:33:39 minikube kubelet[1413]: E0922 15:33:39.375918    1413 kubelet.go:1915] "Failed creating a mirror pod for" err="pods \"kube-controller-manager-minikube\" already exists" pod="kube-system/kube-controller-manager-minikube"
Sep 22 15:33:39 minikube kubelet[1413]: E0922 15:33:39.376273    1413 kubelet.go:1915] "Failed creating a mirror pod for" err="pods \"kube-apiserver-minikube\" already exists" pod="kube-system/kube-apiserver-minikube"
Sep 22 15:33:39 minikube kubelet[1413]: E0922 15:33:39.376392    1413 kubelet.go:1915] "Failed creating a mirror pod for" err="pods \"etcd-minikube\" already exists" pod="kube-system/etcd-minikube"
Sep 22 15:33:39 minikube kubelet[1413]: I0922 15:33:39.392488    1413 pod_startup_latency_tracker.go:104] "Observed pod startup duration" pod="kube-system/kube-scheduler-minikube" podStartSLOduration=1.392433924 podStartE2EDuration="1.392433924s" podCreationTimestamp="2024-09-22 15:33:38 +0000 UTC" firstStartedPulling="0001-01-01 00:00:00 +0000 UTC" lastFinishedPulling="0001-01-01 00:00:00 +0000 UTC" observedRunningTime="2024-09-22 15:33:39.392169972 +0000 UTC m=+1.324137722" watchObservedRunningTime="2024-09-22 15:33:39.392433924 +0000 UTC m=+1.324401677"
Sep 22 15:33:39 minikube kubelet[1413]: I0922 15:33:39.425143    1413 pod_startup_latency_tracker.go:104] "Observed pod startup duration" pod="kube-system/etcd-minikube" podStartSLOduration=1.425127458 podStartE2EDuration="1.425127458s" podCreationTimestamp="2024-09-22 15:33:38 +0000 UTC" firstStartedPulling="0001-01-01 00:00:00 +0000 UTC" lastFinishedPulling="0001-01-01 00:00:00 +0000 UTC" observedRunningTime="2024-09-22 15:33:39.403894521 +0000 UTC m=+1.335862276" watchObservedRunningTime="2024-09-22 15:33:39.425127458 +0000 UTC m=+1.357095221"
Sep 22 15:33:39 minikube kubelet[1413]: I0922 15:33:39.561108    1413 pod_startup_latency_tracker.go:104] "Observed pod startup duration" pod="kube-system/kube-apiserver-minikube" podStartSLOduration=1.5610695749999999 podStartE2EDuration="1.561069575s" podCreationTimestamp="2024-09-22 15:33:38 +0000 UTC" firstStartedPulling="0001-01-01 00:00:00 +0000 UTC" lastFinishedPulling="0001-01-01 00:00:00 +0000 UTC" observedRunningTime="2024-09-22 15:33:39.425416291 +0000 UTC m=+1.357384046" watchObservedRunningTime="2024-09-22 15:33:39.561069575 +0000 UTC m=+1.493037325"
Sep 22 15:33:42 minikube kubelet[1413]: I0922 15:33:42.093309    1413 pod_startup_latency_tracker.go:104] "Observed pod startup duration" pod="kube-system/kube-controller-manager-minikube" podStartSLOduration=4.093222035 podStartE2EDuration="4.093222035s" podCreationTimestamp="2024-09-22 15:33:38 +0000 UTC" firstStartedPulling="0001-01-01 00:00:00 +0000 UTC" lastFinishedPulling="0001-01-01 00:00:00 +0000 UTC" observedRunningTime="2024-09-22 15:33:39.562042961 +0000 UTC m=+1.494010712" watchObservedRunningTime="2024-09-22 15:33:42.093222035 +0000 UTC m=+4.025189787"
Sep 22 15:33:42 minikube kubelet[1413]: I0922 15:33:42.393614    1413 kuberuntime_manager.go:1633] "Updating runtime config through cri with podcidr" CIDR="10.244.0.0/24"
Sep 22 15:33:42 minikube kubelet[1413]: I0922 15:33:42.401245    1413 kubelet_network.go:61] "Updating Pod CIDR" originalPodCIDR="" newPodCIDR="10.244.0.0/24"
Sep 22 15:33:44 minikube kubelet[1413]: I0922 15:33:43.999968    1413 reconciler_common.go:245] "operationExecutor.VerifyControllerAttachedVolume started for volume \"kube-proxy\" (UniqueName: \"kubernetes.io/configmap/5c5883b4-3c04-4504-be18-78081980dad2-kube-proxy\") pod \"kube-proxy-k26zj\" (UID: \"5c5883b4-3c04-4504-be18-78081980dad2\") " pod="kube-system/kube-proxy-k26zj"
Sep 22 15:33:44 minikube kubelet[1413]: I0922 15:33:44.000155    1413 reconciler_common.go:245] "operationExecutor.VerifyControllerAttachedVolume started for volume \"lib-modules\" (UniqueName: \"kubernetes.io/host-path/5c5883b4-3c04-4504-be18-78081980dad2-lib-modules\") pod \"kube-proxy-k26zj\" (UID: \"5c5883b4-3c04-4504-be18-78081980dad2\") " pod="kube-system/kube-proxy-k26zj"
Sep 22 15:33:44 minikube kubelet[1413]: I0922 15:33:44.000178    1413 reconciler_common.go:245] "operationExecutor.VerifyControllerAttachedVolume started for volume \"xtables-lock\" (UniqueName: \"kubernetes.io/host-path/5c5883b4-3c04-4504-be18-78081980dad2-xtables-lock\") pod \"kube-proxy-k26zj\" (UID: \"5c5883b4-3c04-4504-be18-78081980dad2\") " pod="kube-system/kube-proxy-k26zj"
Sep 22 15:33:44 minikube kubelet[1413]: I0922 15:33:44.000214    1413 reconciler_common.go:245] "operationExecutor.VerifyControllerAttachedVolume started for volume \"kube-api-access-jxt5b\" (UniqueName: \"kubernetes.io/projected/5c5883b4-3c04-4504-be18-78081980dad2-kube-api-access-jxt5b\") pod \"kube-proxy-k26zj\" (UID: \"5c5883b4-3c04-4504-be18-78081980dad2\") " pod="kube-system/kube-proxy-k26zj"
Sep 22 15:33:44 minikube kubelet[1413]: I0922 15:33:44.100972    1413 reconciler_common.go:245] "operationExecutor.VerifyControllerAttachedVolume started for volume \"xtables-lock\" (UniqueName: \"kubernetes.io/host-path/c018073a-ca3e-4e9c-ab73-c62850db9041-xtables-lock\") pod \"kindnet-lww7n\" (UID: \"c018073a-ca3e-4e9c-ab73-c62850db9041\") " pod="kube-system/kindnet-lww7n"
Sep 22 15:33:44 minikube kubelet[1413]: I0922 15:33:44.101044    1413 reconciler_common.go:245] "operationExecutor.VerifyControllerAttachedVolume started for volume \"kube-api-access-2hqjg\" (UniqueName: \"kubernetes.io/projected/c018073a-ca3e-4e9c-ab73-c62850db9041-kube-api-access-2hqjg\") pod \"kindnet-lww7n\" (UID: \"c018073a-ca3e-4e9c-ab73-c62850db9041\") " pod="kube-system/kindnet-lww7n"
Sep 22 15:33:44 minikube kubelet[1413]: I0922 15:33:44.101113    1413 reconciler_common.go:245] "operationExecutor.VerifyControllerAttachedVolume started for volume \"cni-cfg\" (UniqueName: \"kubernetes.io/host-path/c018073a-ca3e-4e9c-ab73-c62850db9041-cni-cfg\") pod \"kindnet-lww7n\" (UID: \"c018073a-ca3e-4e9c-ab73-c62850db9041\") " pod="kube-system/kindnet-lww7n"
Sep 22 15:33:44 minikube kubelet[1413]: I0922 15:33:44.101128    1413 reconciler_common.go:245] "operationExecutor.VerifyControllerAttachedVolume started for volume \"lib-modules\" (UniqueName: \"kubernetes.io/host-path/c018073a-ca3e-4e9c-ab73-c62850db9041-lib-modules\") pod \"kindnet-lww7n\" (UID: \"c018073a-ca3e-4e9c-ab73-c62850db9041\") " pod="kube-system/kindnet-lww7n"
Sep 22 15:33:44 minikube kubelet[1413]: I0922 15:33:44.519434    1413 pod_startup_latency_tracker.go:104] "Observed pod startup duration" pod="kube-system/kube-proxy-k26zj" podStartSLOduration=1.519417376 podStartE2EDuration="1.519417376s" podCreationTimestamp="2024-09-22 15:33:43 +0000 UTC" firstStartedPulling="0001-01-01 00:00:00 +0000 UTC" lastFinishedPulling="0001-01-01 00:00:00 +0000 UTC" observedRunningTime="2024-09-22 15:33:44.519286056 +0000 UTC m=+6.451253812" watchObservedRunningTime="2024-09-22 15:33:44.519417376 +0000 UTC m=+6.451385129"
Sep 22 15:33:48 minikube kubelet[1413]: E0922 15:33:48.606787    1413 eviction_manager.go:257] "Eviction manager: failed to get HasDedicatedImageFs" err="missing image stats: &ImageFsInfoResponse{ImageFilesystems:[]*FilesystemUsage{&FilesystemUsage{Timestamp:1727019228398988636,FsId:&FilesystemIdentifier{Mountpoint:/var/lib/containers/storage/overlay-images,},UsedBytes:&UInt64Value{Value:125204,},InodesUsed:&UInt64Value{Value:57,},},},ContainerFilesystems:[]*FilesystemUsage{},}"
Sep 22 15:33:48 minikube kubelet[1413]: E0922 15:33:48.613317    1413 eviction_manager.go:212] "Eviction manager: failed to synchronize" err="eviction manager: failed to get HasDedicatedImageFs: missing image stats: &ImageFsInfoResponse{ImageFilesystems:[]*FilesystemUsage{&FilesystemUsage{Timestamp:1727019228398988636,FsId:&FilesystemIdentifier{Mountpoint:/var/lib/containers/storage/overlay-images,},UsedBytes:&UInt64Value{Value:125204,},InodesUsed:&UInt64Value{Value:57,},},},ContainerFilesystems:[]*FilesystemUsage{},}"
Sep 22 15:33:58 minikube kubelet[1413]: E0922 15:33:58.633944    1413 eviction_manager.go:257] "Eviction manager: failed to get HasDedicatedImageFs" err="missing image stats: &ImageFsInfoResponse{ImageFilesystems:[]*FilesystemUsage{&FilesystemUsage{Timestamp:1727019238626569470,FsId:&FilesystemIdentifier{Mountpoint:/var/lib/containers/storage/overlay-images,},UsedBytes:&UInt64Value{Value:135397,},InodesUsed:&UInt64Value{Value:63,},},},ContainerFilesystems:[]*FilesystemUsage{},}"
Sep 22 15:33:58 minikube kubelet[1413]: E0922 15:33:58.634409    1413 eviction_manager.go:212] "Eviction manager: failed to synchronize" err="eviction manager: failed to get HasDedicatedImageFs: missing image stats: &ImageFsInfoResponse{ImageFilesystems:[]*FilesystemUsage{&FilesystemUsage{Timestamp:1727019238626569470,FsId:&FilesystemIdentifier{Mountpoint:/var/lib/containers/storage/overlay-images,},UsedBytes:&UInt64Value{Value:135397,},InodesUsed:&UInt64Value{Value:63,},},},ContainerFilesystems:[]*FilesystemUsage{},}"
Sep 22 15:34:07 minikube kubelet[1413]: I0922 15:34:07.823097    1413 kubelet_node_status.go:488] "Fast updating node status as it just became ready"
Sep 22 15:34:07 minikube kubelet[1413]: I0922 15:34:07.881432    1413 pod_startup_latency_tracker.go:104] "Observed pod startup duration" pod="kube-system/kindnet-lww7n" podStartSLOduration=17.434736225 podStartE2EDuration="24.881332897s" podCreationTimestamp="2024-09-22 15:33:43 +0000 UTC" firstStartedPulling="2024-09-22 15:33:44.285638597 +0000 UTC m=+6.217606348" lastFinishedPulling="2024-09-22 15:33:51.73223527 +0000 UTC m=+13.664203020" observedRunningTime="2024-09-22 15:33:53.927296238 +0000 UTC m=+15.859263993" watchObservedRunningTime="2024-09-22 15:34:07.881332897 +0000 UTC m=+29.813044834"
Sep 22 15:34:07 minikube kubelet[1413]: I0922 15:34:07.924737    1413 reconciler_common.go:245] "operationExecutor.VerifyControllerAttachedVolume started for volume \"kube-api-access-vlxhq\" (UniqueName: \"kubernetes.io/projected/bcf4063f-9505-4d2f-aada-b287324321ef-kube-api-access-vlxhq\") pod \"coredns-6f6b679f8f-wlp9h\" (UID: \"bcf4063f-9505-4d2f-aada-b287324321ef\") " pod="kube-system/coredns-6f6b679f8f-wlp9h"
Sep 22 15:34:07 minikube kubelet[1413]: I0922 15:34:07.924823    1413 reconciler_common.go:245] "operationExecutor.VerifyControllerAttachedVolume started for volume \"tmp\" (UniqueName: \"kubernetes.io/host-path/90d0e5aa-486b-4746-9a08-c4292728fa8d-tmp\") pod \"storage-provisioner\" (UID: \"90d0e5aa-486b-4746-9a08-c4292728fa8d\") " pod="kube-system/storage-provisioner"
Sep 22 15:34:07 minikube kubelet[1413]: I0922 15:34:07.924909    1413 reconciler_common.go:245] "operationExecutor.VerifyControllerAttachedVolume started for volume \"config-volume\" (UniqueName: \"kubernetes.io/configmap/bcf4063f-9505-4d2f-aada-b287324321ef-config-volume\") pod \"coredns-6f6b679f8f-wlp9h\" (UID: \"bcf4063f-9505-4d2f-aada-b287324321ef\") " pod="kube-system/coredns-6f6b679f8f-wlp9h"
Sep 22 15:34:07 minikube kubelet[1413]: I0922 15:34:07.924957    1413 reconciler_common.go:245] "operationExecutor.VerifyControllerAttachedVolume started for volume \"kube-api-access-r4cbr\" (UniqueName: \"kubernetes.io/projected/90d0e5aa-486b-4746-9a08-c4292728fa8d-kube-api-access-r4cbr\") pod \"storage-provisioner\" (UID: \"90d0e5aa-486b-4746-9a08-c4292728fa8d\") " pod="kube-system/storage-provisioner"
Sep 22 15:34:08 minikube kubelet[1413]: E0922 15:34:08.636432    1413 eviction_manager.go:257] "Eviction manager: failed to get HasDedicatedImageFs" err="missing image stats: &ImageFsInfoResponse{ImageFilesystems:[]*FilesystemUsage{&FilesystemUsage{Timestamp:1727019248636068223,FsId:&FilesystemIdentifier{Mountpoint:/var/lib/containers/storage/overlay-images,},UsedBytes:&UInt64Value{Value:135397,},InodesUsed:&UInt64Value{Value:63,},},},ContainerFilesystems:[]*FilesystemUsage{},}"
Sep 22 15:34:08 minikube kubelet[1413]: E0922 15:34:08.636505    1413 eviction_manager.go:212] "Eviction manager: failed to synchronize" err="eviction manager: failed to get HasDedicatedImageFs: missing image stats: &ImageFsInfoResponse{ImageFilesystems:[]*FilesystemUsage{&FilesystemUsage{Timestamp:1727019248636068223,FsId:&FilesystemIdentifier{Mountpoint:/var/lib/containers/storage/overlay-images,},UsedBytes:&UInt64Value{Value:135397,},InodesUsed:&UInt64Value{Value:63,},},},ContainerFilesystems:[]*FilesystemUsage{},}"
Sep 22 15:34:08 minikube kubelet[1413]: I0922 15:34:08.702490    1413 pod_startup_latency_tracker.go:104] "Observed pod startup duration" pod="kube-system/coredns-6f6b679f8f-wlp9h" podStartSLOduration=25.702472545 podStartE2EDuration="25.702472545s" podCreationTimestamp="2024-09-22 15:33:43 +0000 UTC" firstStartedPulling="0001-01-01 00:00:00 +0000 UTC" lastFinishedPulling="0001-01-01 00:00:00 +0000 UTC" observedRunningTime="2024-09-22 15:34:08.70116246 +0000 UTC m=+30.632874408" watchObservedRunningTime="2024-09-22 15:34:08.702472545 +0000 UTC m=+30.634184490"
Sep 22 15:34:08 minikube kubelet[1413]: I0922 15:34:08.735498    1413 pod_startup_latency_tracker.go:104] "Observed pod startup duration" pod="kube-system/storage-provisioner" podStartSLOduration=26.735465584 podStartE2EDuration="26.735465584s" podCreationTimestamp="2024-09-22 15:33:42 +0000 UTC" firstStartedPulling="0001-01-01 00:00:00 +0000 UTC" lastFinishedPulling="0001-01-01 00:00:00 +0000 UTC" observedRunningTime="2024-09-22 15:34:08.717137185 +0000 UTC m=+30.648849122" watchObservedRunningTime="2024-09-22 15:34:08.735465584 +0000 UTC m=+30.667177519"
Sep 22 15:34:18 minikube kubelet[1413]: E0922 15:34:18.639908    1413 eviction_manager.go:257] "Eviction manager: failed to get HasDedicatedImageFs" err="missing image stats: &ImageFsInfoResponse{ImageFilesystems:[]*FilesystemUsage{&FilesystemUsage{Timestamp:1727019258639462732,FsId:&FilesystemIdentifier{Mountpoint:/var/lib/containers/storage/overlay-images,},UsedBytes:&UInt64Value{Value:135397,},InodesUsed:&UInt64Value{Value:63,},},},ContainerFilesystems:[]*FilesystemUsage{},}"
Sep 22 15:34:18 minikube kubelet[1413]: E0922 15:34:18.640041    1413 eviction_manager.go:212] "Eviction manager: failed to synchronize" err="eviction manager: failed to get HasDedicatedImageFs: missing image stats: &ImageFsInfoResponse{ImageFilesystems:[]*FilesystemUsage{&FilesystemUsage{Timestamp:1727019258639462732,FsId:&FilesystemIdentifier{Mountpoint:/var/lib/containers/storage/overlay-images,},UsedBytes:&UInt64Value{Value:135397,},InodesUsed:&UInt64Value{Value:63,},},},ContainerFilesystems:[]*FilesystemUsage{},}"
Sep 22 15:34:28 minikube kubelet[1413]: E0922 15:34:28.643380    1413 eviction_manager.go:257] "Eviction manager: failed to get HasDedicatedImageFs" err="missing image stats: &ImageFsInfoResponse{ImageFilesystems:[]*FilesystemUsage{&FilesystemUsage{Timestamp:1727019268643046602,FsId:&FilesystemIdentifier{Mountpoint:/var/lib/containers/storage/overlay-images,},UsedBytes:&UInt64Value{Value:135397,},InodesUsed:&UInt64Value{Value:63,},},},ContainerFilesystems:[]*FilesystemUsage{},}"
Sep 22 15:34:28 minikube kubelet[1413]: E0922 15:34:28.643452    1413 eviction_manager.go:212] "Eviction manager: failed to synchronize" err="eviction manager: failed to get HasDedicatedImageFs: missing image stats: &ImageFsInfoResponse{ImageFilesystems:[]*FilesystemUsage{&FilesystemUsage{Timestamp:1727019268643046602,FsId:&FilesystemIdentifier{Mountpoint:/var/lib/containers/storage/overlay-images,},UsedBytes:&UInt64Value{Value:135397,},InodesUsed:&UInt64Value{Value:63,},},},ContainerFilesystems:[]*FilesystemUsage{},}"
Sep 22 15:34:38 minikube kubelet[1413]: E0922 15:34:38.644938    1413 eviction_manager.go:257] "Eviction manager: failed to get HasDedicatedImageFs" err="missing image stats: &ImageFsInfoResponse{ImageFilesystems:[]*FilesystemUsage{&FilesystemUsage{Timestamp:1727019278644539758,FsId:&FilesystemIdentifier{Mountpoint:/var/lib/containers/storage/overlay-images,},UsedBytes:&UInt64Value{Value:135397,},InodesUsed:&UInt64Value{Value:63,},},},ContainerFilesystems:[]*FilesystemUsage{},}"
Sep 22 15:34:38 minikube kubelet[1413]: E0922 15:34:38.645008    1413 eviction_manager.go:212] "Eviction manager: failed to synchronize" err="eviction manager: failed to get HasDedicatedImageFs: missing image stats: &ImageFsInfoResponse{ImageFilesystems:[]*FilesystemUsage{&FilesystemUsage{Timestamp:1727019278644539758,FsId:&FilesystemIdentifier{Mountpoint:/var/lib/containers/storage/overlay-images,},UsedBytes:&UInt64Value{Value:135397,},InodesUsed:&UInt64Value{Value:63,},},},ContainerFilesystems:[]*FilesystemUsage{},}"
Sep 22 15:34:48 minikube kubelet[1413]: E0922 15:34:48.646887    1413 eviction_manager.go:257] "Eviction manager: failed to get HasDedicatedImageFs" err="missing image stats: &ImageFsInfoResponse{ImageFilesystems:[]*FilesystemUsage{&FilesystemUsage{Timestamp:1727019288646596942,FsId:&FilesystemIdentifier{Mountpoint:/var/lib/containers/storage/overlay-images,},UsedBytes:&UInt64Value{Value:135397,},InodesUsed:&UInt64Value{Value:63,},},},ContainerFilesystems:[]*FilesystemUsage{},}"
Sep 22 15:34:48 minikube kubelet[1413]: E0922 15:34:48.646926    1413 eviction_manager.go:212] "Eviction manager: failed to synchronize" err="eviction manager: failed to get HasDedicatedImageFs: missing image stats: &ImageFsInfoResponse{ImageFilesystems:[]*FilesystemUsage{&FilesystemUsage{Timestamp:1727019288646596942,FsId:&FilesystemIdentifier{Mountpoint:/var/lib/containers/storage/overlay-images,},UsedBytes:&UInt64Value{Value:135397,},InodesUsed:&UInt64Value{Value:63,},},},ContainerFilesystems:[]*FilesystemUsage{},}"
Sep 22 15:34:58 minikube kubelet[1413]: E0922 15:34:58.649409    1413 eviction_manager.go:257] "Eviction manager: failed to get HasDedicatedImageFs" err="missing image stats: &ImageFsInfoResponse{ImageFilesystems:[]*FilesystemUsage{&FilesystemUsage{Timestamp:1727019298648899664,FsId:&FilesystemIdentifier{Mountpoint:/var/lib/containers/storage/overlay-images,},UsedBytes:&UInt64Value{Value:135397,},InodesUsed:&UInt64Value{Value:63,},},},ContainerFilesystems:[]*FilesystemUsage{},}"
Sep 22 15:34:58 minikube kubelet[1413]: E0922 15:34:58.649469    1413 eviction_manager.go:212] "Eviction manager: failed to synchronize" err="eviction manager: failed to get HasDedicatedImageFs: missing image stats: &ImageFsInfoResponse{ImageFilesystems:[]*FilesystemUsage{&FilesystemUsage{Timestamp:1727019298648899664,FsId:&FilesystemIdentifier{Mountpoint:/var/lib/containers/storage/overlay-images,},UsedBytes:&UInt64Value{Value:135397,},InodesUsed:&UInt64Value{Value:63,},},},ContainerFilesystems:[]*FilesystemUsage{},}"
Sep 22 15:35:08 minikube kubelet[1413]: E0922 15:35:08.652401    1413 eviction_manager.go:257] "Eviction manager: failed to get HasDedicatedImageFs" err="missing image stats: &ImageFsInfoResponse{ImageFilesystems:[]*FilesystemUsage{&FilesystemUsage{Timestamp:1727019308651912790,FsId:&FilesystemIdentifier{Mountpoint:/var/lib/containers/storage/overlay-images,},UsedBytes:&UInt64Value{Value:135397,},InodesUsed:&UInt64Value{Value:63,},},},ContainerFilesystems:[]*FilesystemUsage{},}"
Sep 22 15:35:08 minikube kubelet[1413]: E0922 15:35:08.652438    1413 eviction_manager.go:212] "Eviction manager: failed to synchronize" err="eviction manager: failed to get HasDedicatedImageFs: missing image stats: &ImageFsInfoResponse{ImageFilesystems:[]*FilesystemUsage{&FilesystemUsage{Timestamp:1727019308651912790,FsId:&FilesystemIdentifier{Mountpoint:/var/lib/containers/storage/overlay-images,},UsedBytes:&UInt64Value{Value:135397,},InodesUsed:&UInt64Value{Value:63,},},},ContainerFilesystems:[]*FilesystemUsage{},}"
Sep 22 15:35:18 minikube kubelet[1413]: E0922 15:35:18.654393    1413 eviction_manager.go:257] "Eviction manager: failed to get HasDedicatedImageFs" err="missing image stats: &ImageFsInfoResponse{ImageFilesystems:[]*FilesystemUsage{&FilesystemUsage{Timestamp:1727019318654039089,FsId:&FilesystemIdentifier{Mountpoint:/var/lib/containers/storage/overlay-images,},UsedBytes:&UInt64Value{Value:135397,},InodesUsed:&UInt64Value{Value:63,},},},ContainerFilesystems:[]*FilesystemUsage{},}"
Sep 22 15:35:18 minikube kubelet[1413]: E0922 15:35:18.654447    1413 eviction_manager.go:212] "Eviction manager: failed to synchronize" err="eviction manager: failed to get HasDedicatedImageFs: missing image stats: &ImageFsInfoResponse{ImageFilesystems:[]*FilesystemUsage{&FilesystemUsage{Timestamp:1727019318654039089,FsId:&FilesystemIdentifier{Mountpoint:/var/lib/containers/storage/overlay-images,},UsedBytes:&UInt64Value{Value:135397,},InodesUsed:&UInt64Value{Value:63,},},},ContainerFilesystems:[]*FilesystemUsage{},}"
Sep 22 15:35:28 minikube kubelet[1413]: E0922 15:35:28.656005    1413 eviction_manager.go:257] "Eviction manager: failed to get HasDedicatedImageFs" err="missing image stats: &ImageFsInfoResponse{ImageFilesystems:[]*FilesystemUsage{&FilesystemUsage{Timestamp:1727019328655552958,FsId:&FilesystemIdentifier{Mountpoint:/var/lib/containers/storage/overlay-images,},UsedBytes:&UInt64Value{Value:135397,},InodesUsed:&UInt64Value{Value:63,},},},ContainerFilesystems:[]*FilesystemUsage{},}"
Sep 22 15:35:28 minikube kubelet[1413]: E0922 15:35:28.656072    1413 eviction_manager.go:212] "Eviction manager: failed to synchronize" err="eviction manager: failed to get HasDedicatedImageFs: missing image stats: &ImageFsInfoResponse{ImageFilesystems:[]*FilesystemUsage{&FilesystemUsage{Timestamp:1727019328655552958,FsId:&FilesystemIdentifier{Mountpoint:/var/lib/containers/storage/overlay-images,},UsedBytes:&UInt64Value{Value:135397,},InodesUsed:&UInt64Value{Value:63,},},},ContainerFilesystems:[]*FilesystemUsage{},}"
Sep 22 15:35:38 minikube kubelet[1413]: E0922 15:35:38.658290    1413 eviction_manager.go:257] "Eviction manager: failed to get HasDedicatedImageFs" err="missing image stats: &ImageFsInfoResponse{ImageFilesystems:[]*FilesystemUsage{&FilesystemUsage{Timestamp:1727019338657898585,FsId:&FilesystemIdentifier{Mountpoint:/var/lib/containers/storage/overlay-images,},UsedBytes:&UInt64Value{Value:135397,},InodesUsed:&UInt64Value{Value:63,},},},ContainerFilesystems:[]*FilesystemUsage{},}"
Sep 22 15:35:38 minikube kubelet[1413]: E0922 15:35:38.658321    1413 eviction_manager.go:212] "Eviction manager: failed to synchronize" err="eviction manager: failed to get HasDedicatedImageFs: missing image stats: &ImageFsInfoResponse{ImageFilesystems:[]*FilesystemUsage{&FilesystemUsage{Timestamp:1727019338657898585,FsId:&FilesystemIdentifier{Mountpoint:/var/lib/containers/storage/overlay-images,},UsedBytes:&UInt64Value{Value:135397,},InodesUsed:&UInt64Value{Value:63,},},},ContainerFilesystems:[]*FilesystemUsage{},}"
Sep 22 15:35:48 minikube kubelet[1413]: E0922 15:35:48.662557    1413 eviction_manager.go:257] "Eviction manager: failed to get HasDedicatedImageFs" err="missing image stats: &ImageFsInfoResponse{ImageFilesystems:[]*FilesystemUsage{&FilesystemUsage{Timestamp:1727019348661913548,FsId:&FilesystemIdentifier{Mountpoint:/var/lib/containers/storage/overlay-images,},UsedBytes:&UInt64Value{Value:135397,},InodesUsed:&UInt64Value{Value:63,},},},ContainerFilesystems:[]*FilesystemUsage{},}"
Sep 22 15:35:48 minikube kubelet[1413]: E0922 15:35:48.662672    1413 eviction_manager.go:212] "Eviction manager: failed to synchronize" err="eviction manager: failed to get HasDedicatedImageFs: missing image stats: &ImageFsInfoResponse{ImageFilesystems:[]*FilesystemUsage{&FilesystemUsage{Timestamp:1727019348661913548,FsId:&FilesystemIdentifier{Mountpoint:/var/lib/containers/storage/overlay-images,},UsedBytes:&UInt64Value{Value:135397,},InodesUsed:&UInt64Value{Value:63,},},},ContainerFilesystems:[]*FilesystemUsage{},}"
Sep 22 15:35:58 minikube kubelet[1413]: E0922 15:35:58.666612    1413 eviction_manager.go:257] "Eviction manager: failed to get HasDedicatedImageFs" err="missing image stats: &ImageFsInfoResponse{ImageFilesystems:[]*FilesystemUsage{&FilesystemUsage{Timestamp:1727019358666097333,FsId:&FilesystemIdentifier{Mountpoint:/var/lib/containers/storage/overlay-images,},UsedBytes:&UInt64Value{Value:135397,},InodesUsed:&UInt64Value{Value:63,},},},ContainerFilesystems:[]*FilesystemUsage{},}"
Sep 22 15:35:58 minikube kubelet[1413]: E0922 15:35:58.666689    1413 eviction_manager.go:212] "Eviction manager: failed to synchronize" err="eviction manager: failed to get HasDedicatedImageFs: missing image stats: &ImageFsInfoResponse{ImageFilesystems:[]*FilesystemUsage{&FilesystemUsage{Timestamp:1727019358666097333,FsId:&FilesystemIdentifier{Mountpoint:/var/lib/containers/storage/overlay-images,},UsedBytes:&UInt64Value{Value:135397,},InodesUsed:&UInt64Value{Value:63,},},},ContainerFilesystems:[]*FilesystemUsage{},}"
Sep 22 15:36:08 minikube kubelet[1413]: E0922 15:36:08.576794    1413 eviction_manager.go:257] "Eviction manager: failed to get HasDedicatedImageFs" err="missing image stats: &ImageFsInfoResponse{ImageFilesystems:[]*FilesystemUsage{&FilesystemUsage{Timestamp:1727019368576336607,FsId:&FilesystemIdentifier{Mountpoint:/var/lib/containers/storage/overlay-images,},UsedBytes:&UInt64Value{Value:135397,},InodesUsed:&UInt64Value{Value:63,},},},ContainerFilesystems:[]*FilesystemUsage{},}"
Sep 22 15:36:08 minikube kubelet[1413]: E0922 15:36:08.576822    1413 eviction_manager.go:212] "Eviction manager: failed to synchronize" err="eviction manager: failed to get HasDedicatedImageFs: missing image stats: &ImageFsInfoResponse{ImageFilesystems:[]*FilesystemUsage{&FilesystemUsage{Timestamp:1727019368576336607,FsId:&FilesystemIdentifier{Mountpoint:/var/lib/containers/storage/overlay-images,},UsedBytes:&UInt64Value{Value:135397,},InodesUsed:&UInt64Value{Value:63,},},},ContainerFilesystems:[]*FilesystemUsage{},}"
Sep 22 15:36:18 minikube kubelet[1413]: E0922 15:36:18.580179    1413 eviction_manager.go:257] "Eviction manager: failed to get HasDedicatedImageFs" err="missing image stats: &ImageFsInfoResponse{ImageFilesystems:[]*FilesystemUsage{&FilesystemUsage{Timestamp:1727019378579802900,FsId:&FilesystemIdentifier{Mountpoint:/var/lib/containers/storage/overlay-images,},UsedBytes:&UInt64Value{Value:135397,},InodesUsed:&UInt64Value{Value:63,},},},ContainerFilesystems:[]*FilesystemUsage{},}"
Sep 22 15:36:18 minikube kubelet[1413]: E0922 15:36:18.580226    1413 eviction_manager.go:212] "Eviction manager: failed to synchronize" err="eviction manager: failed to get HasDedicatedImageFs: missing image stats: &ImageFsInfoResponse{ImageFilesystems:[]*FilesystemUsage{&FilesystemUsage{Timestamp:1727019378579802900,FsId:&FilesystemIdentifier{Mountpoint:/var/lib/containers/storage/overlay-images,},UsedBytes:&UInt64Value{Value:135397,},InodesUsed:&UInt64Value{Value:63,},},},ContainerFilesystems:[]*FilesystemUsage{},}"
Sep 22 15:36:28 minikube kubelet[1413]: E0922 15:36:28.584270    1413 eviction_manager.go:257] "Eviction manager: failed to get HasDedicatedImageFs" err="missing image stats: &ImageFsInfoResponse{ImageFilesystems:[]*FilesystemUsage{&FilesystemUsage{Timestamp:1727019388583783576,FsId:&FilesystemIdentifier{Mountpoint:/var/lib/containers/storage/overlay-images,},UsedBytes:&UInt64Value{Value:135397,},InodesUsed:&UInt64Value{Value:63,},},},ContainerFilesystems:[]*FilesystemUsage{},}"
Sep 22 15:36:28 minikube kubelet[1413]: E0922 15:36:28.584378    1413 eviction_manager.go:212] "Eviction manager: failed to synchronize" err="eviction manager: failed to get HasDedicatedImageFs: missing image stats: &ImageFsInfoResponse{ImageFilesystems:[]*FilesystemUsage{&FilesystemUsage{Timestamp:1727019388583783576,FsId:&FilesystemIdentifier{Mountpoint:/var/lib/containers/storage/overlay-images,},UsedBytes:&UInt64Value{Value:135397,},InodesUsed:&UInt64Value{Value:63,},},},ContainerFilesystems:[]*FilesystemUsage{},}"
Sep 22 15:36:38 minikube kubelet[1413]: E0922 15:36:38.573981    1413 eviction_manager.go:257] "Eviction manager: failed to get HasDedicatedImageFs" err="missing image stats: &ImageFsInfoResponse{ImageFilesystems:[]*FilesystemUsage{&FilesystemUsage{Timestamp:1727019398573601672,FsId:&FilesystemIdentifier{Mountpoint:/var/lib/containers/storage/overlay-images,},UsedBytes:&UInt64Value{Value:135397,},InodesUsed:&UInt64Value{Value:63,},},},ContainerFilesystems:[]*FilesystemUsage{},}"
Sep 22 15:36:38 minikube kubelet[1413]: E0922 15:36:38.574022    1413 eviction_manager.go:212] "Eviction manager: failed to synchronize" err="eviction manager: failed to get HasDedicatedImageFs: missing image stats: &ImageFsInfoResponse{ImageFilesystems:[]*FilesystemUsage{&FilesystemUsage{Timestamp:1727019398573601672,FsId:&FilesystemIdentifier{Mountpoint:/var/lib/containers/storage/overlay-images,},UsedBytes:&UInt64Value{Value:135397,},InodesUsed:&UInt64Value{Value:63,},},},ContainerFilesystems:[]*FilesystemUsage{},}"
Sep 22 15:36:48 minikube kubelet[1413]: E0922 15:36:48.576285    1413 eviction_manager.go:257] "Eviction manager: failed to get HasDedicatedImageFs" err="missing image stats: &ImageFsInfoResponse{ImageFilesystems:[]*FilesystemUsage{&FilesystemUsage{Timestamp:1727019408575873509,FsId:&FilesystemIdentifier{Mountpoint:/var/lib/containers/storage/overlay-images,},UsedBytes:&UInt64Value{Value:135397,},InodesUsed:&UInt64Value{Value:63,},},},ContainerFilesystems:[]*FilesystemUsage{},}"
Sep 22 15:36:48 minikube kubelet[1413]: E0922 15:36:48.576315    1413 eviction_manager.go:212] "Eviction manager: failed to synchronize" err="eviction manager: failed to get HasDedicatedImageFs: missing image stats: &ImageFsInfoResponse{ImageFilesystems:[]*FilesystemUsage{&FilesystemUsage{Timestamp:1727019408575873509,FsId:&FilesystemIdentifier{Mountpoint:/var/lib/containers/storage/overlay-images,},UsedBytes:&UInt64Value{Value:135397,},InodesUsed:&UInt64Value{Value:63,},},},ContainerFilesystems:[]*FilesystemUsage{},}"
Sep 22 15:36:58 minikube kubelet[1413]: E0922 15:36:58.578323    1413 eviction_manager.go:257] "Eviction manager: failed to get HasDedicatedImageFs" err="missing image stats: &ImageFsInfoResponse{ImageFilesystems:[]*FilesystemUsage{&FilesystemUsage{Timestamp:1727019418577861328,FsId:&FilesystemIdentifier{Mountpoint:/var/lib/containers/storage/overlay-images,},UsedBytes:&UInt64Value{Value:135397,},InodesUsed:&UInt64Value{Value:63,},},},ContainerFilesystems:[]*FilesystemUsage{},}"
Sep 22 15:36:58 minikube kubelet[1413]: E0922 15:36:58.578382    1413 eviction_manager.go:212] "Eviction manager: failed to synchronize" err="eviction manager: failed to get HasDedicatedImageFs: missing image stats: &ImageFsInfoResponse{ImageFilesystems:[]*FilesystemUsage{&FilesystemUsage{Timestamp:1727019418577861328,FsId:&FilesystemIdentifier{Mountpoint:/var/lib/containers/storage/overlay-images,},UsedBytes:&UInt64Value{Value:135397,},InodesUsed:&UInt64Value{Value:63,},},},ContainerFilesystems:[]*FilesystemUsage{},}"
Sep 22 15:37:08 minikube kubelet[1413]: E0922 15:37:08.591195    1413 eviction_manager.go:257] "Eviction manager: failed to get HasDedicatedImageFs" err="missing image stats: &ImageFsInfoResponse{ImageFilesystems:[]*FilesystemUsage{&FilesystemUsage{Timestamp:1727019428590755500,FsId:&FilesystemIdentifier{Mountpoint:/var/lib/containers/storage/overlay-images,},UsedBytes:&UInt64Value{Value:135397,},InodesUsed:&UInt64Value{Value:63,},},},ContainerFilesystems:[]*FilesystemUsage{},}"
Sep 22 15:37:08 minikube kubelet[1413]: E0922 15:37:08.591223    1413 eviction_manager.go:212] "Eviction manager: failed to synchronize" err="eviction manager: failed to get HasDedicatedImageFs: missing image stats: &ImageFsInfoResponse{ImageFilesystems:[]*FilesystemUsage{&FilesystemUsage{Timestamp:1727019428590755500,FsId:&FilesystemIdentifier{Mountpoint:/var/lib/containers/storage/overlay-images,},UsedBytes:&UInt64Value{Value:135397,},InodesUsed:&UInt64Value{Value:63,},},},ContainerFilesystems:[]*FilesystemUsage{},}"
Sep 22 15:37:18 minikube kubelet[1413]: E0922 15:37:18.592744    1413 eviction_manager.go:257] "Eviction manager: failed to get HasDedicatedImageFs" err="missing image stats: &ImageFsInfoResponse{ImageFilesystems:[]*FilesystemUsage{&FilesystemUsage{Timestamp:1727019438592454402,FsId:&FilesystemIdentifier{Mountpoint:/var/lib/containers/storage/overlay-images,},UsedBytes:&UInt64Value{Value:135397,},InodesUsed:&UInt64Value{Value:63,},},},ContainerFilesystems:[]*FilesystemUsage{},}"
Sep 22 15:37:18 minikube kubelet[1413]: E0922 15:37:18.592772    1413 eviction_manager.go:212] "Eviction manager: failed to synchronize" err="eviction manager: failed to get HasDedicatedImageFs: missing image stats: &ImageFsInfoResponse{ImageFilesystems:[]*FilesystemUsage{&FilesystemUsage{Timestamp:1727019438592454402,FsId:&FilesystemIdentifier{Mountpoint:/var/lib/containers/storage/overlay-images,},UsedBytes:&UInt64Value{Value:135397,},InodesUsed:&UInt64Value{Value:63,},},},ContainerFilesystems:[]*FilesystemUsage{},}"
Sep 22 15:37:28 minikube kubelet[1413]: E0922 15:37:28.595952    1413 eviction_manager.go:257] "Eviction manager: failed to get HasDedicatedImageFs" err="missing image stats: &ImageFsInfoResponse{ImageFilesystems:[]*FilesystemUsage{&FilesystemUsage{Timestamp:1727019448595522297,FsId:&FilesystemIdentifier{Mountpoint:/var/lib/containers/storage/overlay-images,},UsedBytes:&UInt64Value{Value:135397,},InodesUsed:&UInt64Value{Value:63,},},},ContainerFilesystems:[]*FilesystemUsage{},}"
Sep 22 15:37:28 minikube kubelet[1413]: E0922 15:37:28.596134    1413 eviction_manager.go:212] "Eviction manager: failed to synchronize" err="eviction manager: failed to get HasDedicatedImageFs: missing image stats: &ImageFsInfoResponse{ImageFilesystems:[]*FilesystemUsage{&FilesystemUsage{Timestamp:1727019448595522297,FsId:&FilesystemIdentifier{Mountpoint:/var/lib/containers/storage/overlay-images,},UsedBytes:&UInt64Value{Value:135397,},InodesUsed:&UInt64Value{Value:63,},},},ContainerFilesystems:[]*FilesystemUsage{},}"
Sep 22 15:37:38 minikube kubelet[1413]: E0922 15:37:38.596776    1413 eviction_manager.go:257] "Eviction manager: failed to get HasDedicatedImageFs" err="missing image stats: &ImageFsInfoResponse{ImageFilesystems:[]*FilesystemUsage{&FilesystemUsage{Timestamp:1727019458596310895,FsId:&FilesystemIdentifier{Mountpoint:/var/lib/containers/storage/overlay-images,},UsedBytes:&UInt64Value{Value:135397,},InodesUsed:&UInt64Value{Value:63,},},},ContainerFilesystems:[]*FilesystemUsage{},}"
Sep 22 15:37:38 minikube kubelet[1413]: E0922 15:37:38.596802    1413 eviction_manager.go:212] "Eviction manager: failed to synchronize" err="eviction manager: failed to get HasDedicatedImageFs: missing image stats: &ImageFsInfoResponse{ImageFilesystems:[]*FilesystemUsage{&FilesystemUsage{Timestamp:1727019458596310895,FsId:&FilesystemIdentifier{Mountpoint:/var/lib/containers/storage/overlay-images,},UsedBytes:&UInt64Value{Value:135397,},InodesUsed:&UInt64Value{Value:63,},},},ContainerFilesystems:[]*FilesystemUsage{},}"
Sep 22 15:37:48 minikube kubelet[1413]: E0922 15:37:48.598860    1413 eviction_manager.go:257] "Eviction manager: failed to get HasDedicatedImageFs" err="missing image stats: &ImageFsInfoResponse{ImageFilesystems:[]*FilesystemUsage{&FilesystemUsage{Timestamp:1727019468598566251,FsId:&FilesystemIdentifier{Mountpoint:/var/lib/containers/storage/overlay-images,},UsedBytes:&UInt64Value{Value:135397,},InodesUsed:&UInt64Value{Value:63,},},},ContainerFilesystems:[]*FilesystemUsage{},}"
Sep 22 15:37:48 minikube kubelet[1413]: E0922 15:37:48.598882    1413 eviction_manager.go:212] "Eviction manager: failed to synchronize" err="eviction manager: failed to get HasDedicatedImageFs: missing image stats: &ImageFsInfoResponse{ImageFilesystems:[]*FilesystemUsage{&FilesystemUsage{Timestamp:1727019468598566251,FsId:&FilesystemIdentifier{Mountpoint:/var/lib/containers/storage/overlay-images,},UsedBytes:&UInt64Value{Value:135397,},InodesUsed:&UInt64Value{Value:63,},},},ContainerFilesystems:[]*FilesystemUsage{},}"
Sep 22 15:37:58 minikube kubelet[1413]: E0922 15:37:58.600656    1413 eviction_manager.go:257] "Eviction manager: failed to get HasDedicatedImageFs" err="missing image stats: &ImageFsInfoResponse{ImageFilesystems:[]*FilesystemUsage{&FilesystemUsage{Timestamp:1727019478600315142,FsId:&FilesystemIdentifier{Mountpoint:/var/lib/containers/storage/overlay-images,},UsedBytes:&UInt64Value{Value:135397,},InodesUsed:&UInt64Value{Value:63,},},},ContainerFilesystems:[]*FilesystemUsage{},}"
Sep 22 15:37:58 minikube kubelet[1413]: E0922 15:37:58.600697    1413 eviction_manager.go:212] "Eviction manager: failed to synchronize" err="eviction manager: failed to get HasDedicatedImageFs: missing image stats: &ImageFsInfoResponse{ImageFilesystems:[]*FilesystemUsage{&FilesystemUsage{Timestamp:1727019478600315142,FsId:&FilesystemIdentifier{Mountpoint:/var/lib/containers/storage/overlay-images,},UsedBytes:&UInt64Value{Value:135397,},InodesUsed:&UInt64Value{Value:63,},},},ContainerFilesystems:[]*FilesystemUsage{},}"
Sep 22 15:38:08 minikube kubelet[1413]: E0922 15:38:08.602459    1413 eviction_manager.go:257] "Eviction manager: failed to get HasDedicatedImageFs" err="missing image stats: &ImageFsInfoResponse{ImageFilesystems:[]*FilesystemUsage{&FilesystemUsage{Timestamp:1727019488601944418,FsId:&FilesystemIdentifier{Mountpoint:/var/lib/containers/storage/overlay-images,},UsedBytes:&UInt64Value{Value:135397,},InodesUsed:&UInt64Value{Value:63,},},},ContainerFilesystems:[]*FilesystemUsage{},}"
Sep 22 15:38:08 minikube kubelet[1413]: E0922 15:38:08.602535    1413 eviction_manager.go:212] "Eviction manager: failed to synchronize" err="eviction manager: failed to get HasDedicatedImageFs: missing image stats: &ImageFsInfoResponse{ImageFilesystems:[]*FilesystemUsage{&FilesystemUsage{Timestamp:1727019488601944418,FsId:&FilesystemIdentifier{Mountpoint:/var/lib/containers/storage/overlay-images,},UsedBytes:&UInt64Value{Value:135397,},InodesUsed:&UInt64Value{Value:63,},},},ContainerFilesystems:[]*FilesystemUsage{},}"